2020-01-27 13:45:30,376 log_support.py[line:36] INFO -init logging module success
2020-01-27 13:45:31,093 load_json.py[line:29] INFO json loaded at time 2020-01-27 13:45:31
2020-01-27 13:45:31,094 load_json.py[line:90] INFO data constructed
2020-01-27 13:46:39,486 log_support.py[line:36] INFO -init logging module success
2020-01-27 13:46:41,978 load_json.py[line:29] INFO json loaded at time 2020-01-27 13:46:41
2020-01-27 13:46:41,980 load_json.py[line:90] INFO data constructed
2020-01-27 13:46:41,980 load_json.py[line:101] INFO data updated at 1580104001.9803023
2020-01-27 13:47:42,289 load_json.py[line:29] INFO json loaded at time 2020-01-27 13:47:42
2020-01-27 13:48:57,231 load_json.py[line:32] ERROR json load failed, waiting for around 15 seconds
2020-01-27 13:48:57,231 load_json.py[line:33] ERROR 'data'
Traceback (most recent call last):
  File "load_json.py", line 27, in load_response
    if not response['data']['listByArea']:
KeyError: 'data'
2020-01-27 13:49:15,202 load_json.py[line:29] INFO json loaded at time 2020-01-27 13:49:15
2020-01-27 13:50:10,672 load_json.py[line:29] INFO json loaded at time 2020-01-27 13:50:10
2020-01-27 13:51:00,421 log_support.py[line:36] INFO -init logging module success
2020-01-27 13:51:01,569 load_json.py[line:29] INFO json loaded at time 2020-01-27 13:51:01
2020-01-27 13:51:01,570 load_json.py[line:90] INFO data constructed
2020-01-27 13:51:01,570 load_json.py[line:101] INFO data updated at 1580104261.56915
2020-01-27 13:51:28,437 log_support.py[line:36] INFO -init logging module success
2020-01-27 13:51:29,244 load_json.py[line:30] INFO json loaded at time 2020-01-27 13:51:29
2020-01-27 13:51:29,244 load_json.py[line:91] INFO data constructed
2020-01-27 13:51:29,244 load_json.py[line:102] INFO data updated at 1580104289.2447329
2020-01-27 13:52:36,134 load_json.py[line:30] INFO json loaded at time 2020-01-27 13:52:36
2020-01-27 13:52:37,351 load_json.py[line:30] INFO json loaded at time 2020-01-27 13:52:37
2020-01-27 13:52:37,352 load_json.py[line:91] INFO data constructed
2020-01-27 13:52:37,352 load_json.py[line:102] INFO data updated at 1580104357.3526285
2020-01-27 13:53:32,595 load_json.py[line:33] ERROR json load failed, waiting for around 15 seconds
2020-01-27 13:53:32,595 load_json.py[line:34] ERROR 'data'
Traceback (most recent call last):
  File "load_json.py", line 28, in load_response
    if not response['data']['listByArea']:
KeyError: 'data'
2020-01-27 13:53:50,196 load_json.py[line:30] INFO json loaded at time 2020-01-27 13:53:50
2020-01-27 13:54:38,458 load_json.py[line:33] ERROR json load failed, waiting for around 15 seconds
2020-01-27 13:54:38,458 load_json.py[line:34] ERROR 'data'
Traceback (most recent call last):
  File "load_json.py", line 28, in load_response
    if not response['data']['listByArea']:
KeyError: 'data'
2020-01-27 13:54:58,602 load_json.py[line:30] INFO json loaded at time 2020-01-27 13:54:58
2020-01-27 13:55:44,875 load_json.py[line:30] INFO json loaded at time 2020-01-27 13:55:44
2020-01-27 13:56:24,479 log_support.py[line:36] INFO -init logging module success
2020-01-27 13:56:25,335 load_json.py[line:30] INFO json loaded at time 2020-01-27 13:56:25
2020-01-27 13:56:25,337 load_json.py[line:91] INFO data constructed
2020-01-27 13:56:25,337 load_json.py[line:102] INFO data updated at 1580104585.3366685
2020-01-27 13:56:40,056 load_json.py[line:30] INFO json loaded at time 2020-01-27 13:56:40
2020-01-27 13:56:56,989 log_support.py[line:36] INFO -init logging module success
2020-01-27 13:56:57,295 load_json.py[line:33] ERROR json load failed, waiting for around 15 seconds
2020-01-27 13:56:57,295 load_json.py[line:34] ERROR 'data'
Traceback (most recent call last):
  File "load_json.py", line 28, in load_response
    if not response['data']['listByArea']:
KeyError: 'data'
2020-01-27 13:57:16,308 load_json.py[line:30] INFO json loaded at time 2020-01-27 13:57:16
2020-01-27 13:57:16,309 load_json.py[line:91] INFO data constructed
2020-01-27 13:57:16,309 load_json.py[line:102] INFO data updated at 1580104636.309584
2020-01-27 13:57:25,598 load_json.py[line:30] INFO json loaded at time 2020-01-27 13:57:25
2020-01-27 13:57:26,385 load_json.py[line:30] INFO json loaded at time 2020-01-27 13:57:26
2020-01-27 13:57:26,386 load_json.py[line:91] INFO data constructed
2020-01-27 13:57:26,387 load_json.py[line:102] INFO data updated at 1580104646.3861601
2020-01-27 14:00:04,667 log_support.py[line:36] INFO -init logging module success
2020-01-27 14:00:05,456 load_json.py[line:30] INFO json loaded at time 2020-01-27 14:00:05
2020-01-27 14:00:05,456 load_json.py[line:91] INFO data constructed
2020-01-27 14:00:05,456 load_json.py[line:102] INFO data updated at 1580104805.4562585
2020-01-27 14:00:16,440 load_json.py[line:30] INFO json loaded at time 2020-01-27 14:00:16
2020-01-27 14:00:28,515 load_json.py[line:30] INFO json loaded at time 2020-01-27 14:00:28
2020-01-27 14:00:40,916 load_json.py[line:30] INFO json loaded at time 2020-01-27 14:00:40
2020-01-27 14:00:54,880 load_json.py[line:33] ERROR json load failed, waiting for around 15 seconds
2020-01-27 14:00:54,881 load_json.py[line:34] ERROR 'data'
Traceback (most recent call last):
  File "load_json.py", line 28, in load_response
    if not response['data']['listByArea']:
KeyError: 'data'
2020-01-27 14:01:10,749 log_support.py[line:36] INFO -init logging module success
2020-01-27 14:01:11,644 load_json.py[line:30] INFO json loaded at time 2020-01-27 14:01:11
2020-01-27 14:01:11,644 load_json.py[line:91] INFO data constructed
2020-01-27 14:01:11,644 load_json.py[line:102] INFO data updated at 1580104871.6440444
2020-01-27 14:01:18,762 load_json.py[line:30] INFO json loaded at time 2020-01-27 14:01:18
2020-01-27 14:01:25,487 load_json.py[line:30] INFO json loaded at time 2020-01-27 14:01:25
2020-01-27 14:01:38,572 load_json.py[line:30] INFO json loaded at time 2020-01-27 14:01:38
2020-01-27 14:01:48,079 load_json.py[line:33] ERROR json load failed, waiting for around 15 seconds
2020-01-27 14:01:48,079 load_json.py[line:34] ERROR 'data'
Traceback (most recent call last):
  File "load_json.py", line 28, in load_response
    if not response['data']['listByArea']:
KeyError: 'data'
2020-01-27 14:02:08,385 load_json.py[line:30] INFO json loaded at time 2020-01-27 14:02:08
2020-01-27 14:02:21,153 load_json.py[line:33] ERROR json load failed, waiting for around 15 seconds
2020-01-27 14:02:21,154 load_json.py[line:34] ERROR 'data'
Traceback (most recent call last):
  File "load_json.py", line 28, in load_response
    if not response['data']['listByArea']:
KeyError: 'data'
2020-01-27 14:02:40,950 load_json.py[line:33] ERROR json load failed, waiting for around 15 seconds
2020-01-27 14:02:40,950 load_json.py[line:34] ERROR 'data'
Traceback (most recent call last):
  File "load_json.py", line 28, in load_response
    if not response['data']['listByArea']:
KeyError: 'data'

During handling of the above exception, another exception occurred:

Traceback (most recent call last):
  File "load_json.py", line 28, in load_response
    if not response['data']['listByArea']:
KeyError: 'data'
2020-01-27 14:03:00,329 load_json.py[line:33] ERROR json load failed, waiting for around 15 seconds
2020-01-27 14:03:00,329 load_json.py[line:34] ERROR 'data'
Traceback (most recent call last):
  File "load_json.py", line 28, in load_response
    if not response['data']['listByArea']:
KeyError: 'data'

During handling of the above exception, another exception occurred:

Traceback (most recent call last):
  File "load_json.py", line 28, in load_response
    if not response['data']['listByArea']:
KeyError: 'data'

During handling of the above exception, another exception occurred:

Traceback (most recent call last):
  File "load_json.py", line 28, in load_response
    if not response['data']['listByArea']:
KeyError: 'data'
2020-01-27 14:03:18,517 load_json.py[line:30] INFO json loaded at time 2020-01-27 14:03:18
2020-01-27 14:03:26,532 load_json.py[line:30] INFO json loaded at time 2020-01-27 14:03:26
2020-01-27 14:03:39,826 load_json.py[line:30] INFO json loaded at time 2020-01-27 14:03:39
2020-01-27 14:03:54,333 load_json.py[line:30] INFO json loaded at time 2020-01-27 14:03:54
2020-01-27 14:04:04,094 load_json.py[line:33] ERROR json load failed, waiting for around 15 seconds
2020-01-27 14:04:04,094 load_json.py[line:34] ERROR 'data'
Traceback (most recent call last):
  File "load_json.py", line 28, in load_response
    if not response['data']['listByArea']:
KeyError: 'data'
2020-01-27 14:04:24,147 load_json.py[line:33] ERROR json load failed, waiting for around 15 seconds
2020-01-27 14:04:24,148 load_json.py[line:34] ERROR 'data'
Traceback (most recent call last):
  File "load_json.py", line 28, in load_response
    if not response['data']['listByArea']:
KeyError: 'data'

During handling of the above exception, another exception occurred:

Traceback (most recent call last):
  File "load_json.py", line 28, in load_response
    if not response['data']['listByArea']:
KeyError: 'data'
2020-01-27 14:04:44,560 load_json.py[line:30] INFO json loaded at time 2020-01-27 14:04:44
2020-01-27 14:04:58,544 load_json.py[line:30] INFO json loaded at time 2020-01-27 14:04:58
2020-01-27 14:05:14,232 load_json.py[line:30] INFO json loaded at time 2020-01-27 14:05:14
2020-01-27 14:05:28,166 load_json.py[line:33] ERROR json load failed, waiting for around 15 seconds
2020-01-27 14:05:28,167 load_json.py[line:34] ERROR 'data'
Traceback (most recent call last):
  File "load_json.py", line 28, in load_response
    if not response['data']['listByArea']:
KeyError: 'data'
2020-01-27 14:05:46,864 load_json.py[line:30] INFO json loaded at time 2020-01-27 14:05:46
2020-01-27 14:05:57,744 load_json.py[line:30] INFO json loaded at time 2020-01-27 14:05:57
2020-01-27 14:06:12,144 load_json.py[line:33] ERROR json load failed, waiting for around 15 seconds
2020-01-27 14:06:12,144 load_json.py[line:34] ERROR 'data'
Traceback (most recent call last):
  File "load_json.py", line 28, in load_response
    if not response['data']['listByArea']:
KeyError: 'data'
2020-01-27 14:06:28,171 load_json.py[line:33] ERROR json load failed, waiting for around 15 seconds
2020-01-27 14:06:28,171 load_json.py[line:34] ERROR 'data'
Traceback (most recent call last):
  File "load_json.py", line 28, in load_response
    if not response['data']['listByArea']:
KeyError: 'data'

During handling of the above exception, another exception occurred:

Traceback (most recent call last):
  File "load_json.py", line 28, in load_response
    if not response['data']['listByArea']:
KeyError: 'data'
2020-01-27 14:06:44,304 load_json.py[line:30] INFO json loaded at time 2020-01-27 14:06:44
2020-01-27 14:06:58,757 load_json.py[line:33] ERROR json load failed, waiting for around 15 seconds
2020-01-27 14:06:58,757 load_json.py[line:34] ERROR 'data'
Traceback (most recent call last):
  File "load_json.py", line 28, in load_response
    if not response['data']['listByArea']:
KeyError: 'data'
2020-01-27 14:07:15,926 load_json.py[line:33] ERROR json load failed, waiting for around 15 seconds
2020-01-27 14:07:15,926 load_json.py[line:34] ERROR 'data'
Traceback (most recent call last):
  File "load_json.py", line 28, in load_response
    if not response['data']['listByArea']:
KeyError: 'data'

During handling of the above exception, another exception occurred:

Traceback (most recent call last):
  File "load_json.py", line 28, in load_response
    if not response['data']['listByArea']:
KeyError: 'data'
2020-01-27 14:07:32,370 load_json.py[line:30] INFO json loaded at time 2020-01-27 14:07:32
2020-01-27 14:07:44,454 load_json.py[line:30] INFO json loaded at time 2020-01-27 14:07:44
2020-01-27 14:08:00,112 load_json.py[line:30] INFO json loaded at time 2020-01-27 14:08:00
2020-01-27 14:08:13,252 load_json.py[line:33] ERROR json load failed, waiting for around 15 seconds
2020-01-27 14:08:13,252 load_json.py[line:34] ERROR 'data'
Traceback (most recent call last):
  File "load_json.py", line 28, in load_response
    if not response['data']['listByArea']:
KeyError: 'data'
2020-01-27 14:08:31,360 load_json.py[line:30] INFO json loaded at time 2020-01-27 14:08:31
2020-01-27 14:08:46,438 load_json.py[line:30] INFO json loaded at time 2020-01-27 14:08:46
2020-01-27 14:08:56,014 load_json.py[line:30] INFO json loaded at time 2020-01-27 14:08:56
2020-01-27 14:09:02,676 load_json.py[line:30] INFO json loaded at time 2020-01-27 14:09:02
2020-01-27 14:09:12,598 load_json.py[line:33] ERROR json load failed, waiting for around 15 seconds
2020-01-27 14:09:12,598 load_json.py[line:34] ERROR 'data'
Traceback (most recent call last):
  File "load_json.py", line 28, in load_response
    if not response['data']['listByArea']:
KeyError: 'data'
2020-01-27 14:09:30,014 load_json.py[line:30] INFO json loaded at time 2020-01-27 14:09:30
2020-01-27 14:09:44,453 load_json.py[line:30] INFO json loaded at time 2020-01-27 14:09:44
2020-01-27 14:09:57,970 load_json.py[line:30] INFO json loaded at time 2020-01-27 14:09:57
2020-01-27 14:10:13,589 load_json.py[line:30] INFO json loaded at time 2020-01-27 14:10:13
2020-01-27 14:10:23,289 load_json.py[line:30] INFO json loaded at time 2020-01-27 14:10:23
2020-01-27 14:10:34,458 load_json.py[line:30] INFO json loaded at time 2020-01-27 14:10:34
2020-01-27 14:10:43,924 load_json.py[line:30] INFO json loaded at time 2020-01-27 14:10:43
2020-01-27 14:10:54,186 load_json.py[line:30] INFO json loaded at time 2020-01-27 14:10:54
2020-01-27 14:11:01,525 load_json.py[line:33] ERROR json load failed, waiting for around 15 seconds
2020-01-27 14:11:01,525 load_json.py[line:34] ERROR 'data'
Traceback (most recent call last):
  File "load_json.py", line 28, in load_response
    if not response['data']['listByArea']:
KeyError: 'data'
2020-01-27 14:11:18,233 load_json.py[line:33] ERROR json load failed, waiting for around 15 seconds
2020-01-27 14:11:18,234 load_json.py[line:34] ERROR 'data'
Traceback (most recent call last):
  File "load_json.py", line 28, in load_response
    if not response['data']['listByArea']:
KeyError: 'data'

During handling of the above exception, another exception occurred:

Traceback (most recent call last):
  File "load_json.py", line 28, in load_response
    if not response['data']['listByArea']:
KeyError: 'data'
2020-01-27 14:11:38,561 load_json.py[line:33] ERROR json load failed, waiting for around 15 seconds
2020-01-27 14:11:38,562 load_json.py[line:34] ERROR 'data'
Traceback (most recent call last):
  File "load_json.py", line 28, in load_response
    if not response['data']['listByArea']:
KeyError: 'data'

During handling of the above exception, another exception occurred:

Traceback (most recent call last):
  File "load_json.py", line 28, in load_response
    if not response['data']['listByArea']:
KeyError: 'data'

During handling of the above exception, another exception occurred:

Traceback (most recent call last):
  File "load_json.py", line 28, in load_response
    if not response['data']['listByArea']:
KeyError: 'data'
2020-01-27 14:11:54,608 load_json.py[line:30] INFO json loaded at time 2020-01-27 14:11:54
2020-01-27 14:12:07,519 load_json.py[line:30] INFO json loaded at time 2020-01-27 14:12:07
2020-01-27 14:12:21,085 load_json.py[line:30] INFO json loaded at time 2020-01-27 14:12:21
2020-01-27 14:12:32,168 load_json.py[line:33] ERROR json load failed, waiting for around 15 seconds
2020-01-27 14:12:32,168 load_json.py[line:34] ERROR 'data'
Traceback (most recent call last):
  File "load_json.py", line 28, in load_response
    if not response['data']['listByArea']:
KeyError: 'data'
2020-01-27 14:12:50,282 load_json.py[line:30] INFO json loaded at time 2020-01-27 14:12:50
2020-01-27 14:12:59,608 load_json.py[line:30] INFO json loaded at time 2020-01-27 14:12:59
2020-01-27 14:13:11,103 load_json.py[line:30] INFO json loaded at time 2020-01-27 14:13:11
2020-01-27 14:13:24,479 load_json.py[line:30] INFO json loaded at time 2020-01-27 14:13:24
2020-01-27 14:13:39,189 load_json.py[line:30] INFO json loaded at time 2020-01-27 14:13:39
2020-01-27 14:13:49,655 load_json.py[line:33] ERROR json load failed, waiting for around 15 seconds
2020-01-27 14:13:49,656 load_json.py[line:34] ERROR 'data'
Traceback (most recent call last):
  File "load_json.py", line 28, in load_response
    if not response['data']['listByArea']:
KeyError: 'data'
2020-01-27 14:14:09,092 load_json.py[line:30] INFO json loaded at time 2020-01-27 14:14:09
2020-01-27 14:14:20,490 load_json.py[line:30] INFO json loaded at time 2020-01-27 14:14:20
2020-01-27 14:14:31,047 load_json.py[line:33] ERROR json load failed, waiting for around 15 seconds
2020-01-27 14:14:31,048 load_json.py[line:34] ERROR 'data'
Traceback (most recent call last):
  File "load_json.py", line 28, in load_response
    if not response['data']['listByArea']:
KeyError: 'data'
2020-01-27 14:14:49,914 load_json.py[line:30] INFO json loaded at time 2020-01-27 14:14:49
2020-01-27 14:14:57,212 load_json.py[line:30] INFO json loaded at time 2020-01-27 14:14:57
2020-01-27 14:15:06,780 load_json.py[line:30] INFO json loaded at time 2020-01-27 14:15:06
2020-01-27 14:15:24,298 load_json.py[line:30] INFO json loaded at time 2020-01-27 14:15:24
2020-01-27 14:15:33,657 load_json.py[line:30] INFO json loaded at time 2020-01-27 14:15:33
2020-01-27 14:15:43,493 load_json.py[line:30] INFO json loaded at time 2020-01-27 14:15:43
2020-01-27 14:15:56,785 load_json.py[line:30] INFO json loaded at time 2020-01-27 14:15:56
2020-01-27 14:16:07,474 load_json.py[line:30] INFO json loaded at time 2020-01-27 14:16:07
2020-01-27 14:16:16,034 load_json.py[line:30] INFO json loaded at time 2020-01-27 14:16:16
2020-01-27 14:16:22,916 load_json.py[line:30] INFO json loaded at time 2020-01-27 14:16:22
2020-01-27 14:16:31,341 load_json.py[line:33] ERROR json load failed, waiting for around 15 seconds
2020-01-27 14:16:31,341 load_json.py[line:34] ERROR 'data'
Traceback (most recent call last):
  File "load_json.py", line 28, in load_response
    if not response['data']['listByArea']:
KeyError: 'data'
2020-01-27 14:16:47,867 load_json.py[line:33] ERROR json load failed, waiting for around 15 seconds
2020-01-27 14:16:47,867 load_json.py[line:34] ERROR 'data'
Traceback (most recent call last):
  File "load_json.py", line 28, in load_response
    if not response['data']['listByArea']:
KeyError: 'data'

During handling of the above exception, another exception occurred:

Traceback (most recent call last):
  File "load_json.py", line 28, in load_response
    if not response['data']['listByArea']:
KeyError: 'data'
2020-01-27 14:17:07,102 load_json.py[line:33] ERROR json load failed, waiting for around 15 seconds
2020-01-27 14:17:07,103 load_json.py[line:34] ERROR 'data'
Traceback (most recent call last):
  File "load_json.py", line 28, in load_response
    if not response['data']['listByArea']:
KeyError: 'data'

During handling of the above exception, another exception occurred:

Traceback (most recent call last):
  File "load_json.py", line 28, in load_response
    if not response['data']['listByArea']:
KeyError: 'data'

During handling of the above exception, another exception occurred:

Traceback (most recent call last):
  File "load_json.py", line 28, in load_response
    if not response['data']['listByArea']:
KeyError: 'data'
2020-01-27 14:17:27,772 load_json.py[line:30] INFO json loaded at time 2020-01-27 14:17:27
2020-01-27 14:17:42,515 load_json.py[line:30] INFO json loaded at time 2020-01-27 14:17:42
2020-01-27 14:17:55,170 load_json.py[line:30] INFO json loaded at time 2020-01-27 14:17:55
2020-01-27 14:18:07,557 load_json.py[line:30] INFO json loaded at time 2020-01-27 14:18:07
2020-01-27 14:18:21,174 load_json.py[line:30] INFO json loaded at time 2020-01-27 14:18:21
2020-01-27 14:18:37,017 load_json.py[line:30] INFO json loaded at time 2020-01-27 14:18:37
2020-01-27 14:18:45,440 load_json.py[line:33] ERROR json load failed, waiting for around 15 seconds
2020-01-27 14:18:45,440 load_json.py[line:34] ERROR 'data'
Traceback (most recent call last):
  File "load_json.py", line 28, in load_response
    if not response['data']['listByArea']:
KeyError: 'data'
2020-01-27 14:19:01,703 load_json.py[line:33] ERROR json load failed, waiting for around 15 seconds
2020-01-27 14:19:01,703 load_json.py[line:34] ERROR 'data'
Traceback (most recent call last):
  File "load_json.py", line 28, in load_response
    if not response['data']['listByArea']:
KeyError: 'data'

During handling of the above exception, another exception occurred:

Traceback (most recent call last):
  File "load_json.py", line 28, in load_response
    if not response['data']['listByArea']:
KeyError: 'data'
2020-01-27 14:19:21,245 load_json.py[line:33] ERROR json load failed, waiting for around 15 seconds
2020-01-27 14:19:21,246 load_json.py[line:34] ERROR 'data'
Traceback (most recent call last):
  File "load_json.py", line 28, in load_response
    if not response['data']['listByArea']:
KeyError: 'data'

During handling of the above exception, another exception occurred:

Traceback (most recent call last):
  File "load_json.py", line 28, in load_response
    if not response['data']['listByArea']:
KeyError: 'data'

During handling of the above exception, another exception occurred:

Traceback (most recent call last):
  File "load_json.py", line 28, in load_response
    if not response['data']['listByArea']:
KeyError: 'data'
2020-01-27 14:19:40,470 load_json.py[line:30] INFO json loaded at time 2020-01-27 14:19:40
2020-01-27 14:19:54,058 load_json.py[line:30] INFO json loaded at time 2020-01-27 14:19:54
2020-01-27 14:20:09,043 load_json.py[line:33] ERROR json load failed, waiting for around 15 seconds
2020-01-27 14:20:09,043 load_json.py[line:34] ERROR 'data'
Traceback (most recent call last):
  File "load_json.py", line 28, in load_response
    if not response['data']['listByArea']:
KeyError: 'data'
2020-01-27 14:20:28,644 load_json.py[line:33] ERROR json load failed, waiting for around 15 seconds
2020-01-27 14:20:28,645 load_json.py[line:34] ERROR 'data'
Traceback (most recent call last):
  File "load_json.py", line 28, in load_response
    if not response['data']['listByArea']:
KeyError: 'data'

During handling of the above exception, another exception occurred:

Traceback (most recent call last):
  File "load_json.py", line 28, in load_response
    if not response['data']['listByArea']:
KeyError: 'data'
2020-01-27 14:20:48,480 load_json.py[line:33] ERROR json load failed, waiting for around 15 seconds
2020-01-27 14:20:48,481 load_json.py[line:34] ERROR 'data'
Traceback (most recent call last):
  File "load_json.py", line 28, in load_response
    if not response['data']['listByArea']:
KeyError: 'data'

During handling of the above exception, another exception occurred:

Traceback (most recent call last):
  File "load_json.py", line 28, in load_response
    if not response['data']['listByArea']:
KeyError: 'data'

During handling of the above exception, another exception occurred:

Traceback (most recent call last):
  File "load_json.py", line 28, in load_response
    if not response['data']['listByArea']:
KeyError: 'data'
2020-01-27 14:21:05,872 load_json.py[line:30] INFO json loaded at time 2020-01-27 14:21:05
2020-01-27 14:21:12,823 load_json.py[line:30] INFO json loaded at time 2020-01-27 14:21:12
2020-01-27 14:21:21,627 load_json.py[line:30] INFO json loaded at time 2020-01-27 14:21:21
2020-01-27 14:21:32,388 load_json.py[line:33] ERROR json load failed, waiting for around 15 seconds
2020-01-27 14:21:32,389 load_json.py[line:34] ERROR 'data'
Traceback (most recent call last):
  File "load_json.py", line 28, in load_response
    if not response['data']['listByArea']:
KeyError: 'data'
2020-01-27 14:21:49,734 load_json.py[line:30] INFO json loaded at time 2020-01-27 14:21:49
2020-01-27 14:21:58,168 load_json.py[line:30] INFO json loaded at time 2020-01-27 14:21:58
2020-01-27 14:22:06,368 load_json.py[line:33] ERROR json load failed, waiting for around 15 seconds
2020-01-27 14:22:06,369 load_json.py[line:34] ERROR 'data'
Traceback (most recent call last):
  File "load_json.py", line 28, in load_response
    if not response['data']['listByArea']:
KeyError: 'data'
2020-01-27 14:22:24,006 load_json.py[line:33] ERROR json load failed, waiting for around 15 seconds
2020-01-27 14:22:24,006 load_json.py[line:34] ERROR 'data'
Traceback (most recent call last):
  File "load_json.py", line 28, in load_response
    if not response['data']['listByArea']:
KeyError: 'data'

During handling of the above exception, another exception occurred:

Traceback (most recent call last):
  File "load_json.py", line 28, in load_response
    if not response['data']['listByArea']:
KeyError: 'data'
2020-01-27 14:22:43,069 load_json.py[line:30] INFO json loaded at time 2020-01-27 14:22:43
2020-01-27 14:22:50,981 load_json.py[line:30] INFO json loaded at time 2020-01-27 14:22:50
2020-01-27 14:23:03,285 load_json.py[line:30] INFO json loaded at time 2020-01-27 14:23:03
2020-01-27 14:23:16,322 load_json.py[line:30] INFO json loaded at time 2020-01-27 14:23:16
2020-01-27 14:23:22,706 load_json.py[line:33] ERROR json load failed, waiting for around 15 seconds
2020-01-27 14:23:22,706 load_json.py[line:34] ERROR 'data'
Traceback (most recent call last):
  File "load_json.py", line 28, in load_response
    if not response['data']['listByArea']:
KeyError: 'data'
2020-01-27 14:23:42,153 load_json.py[line:33] ERROR json load failed, waiting for around 15 seconds
2020-01-27 14:23:42,154 load_json.py[line:34] ERROR 'data'
Traceback (most recent call last):
  File "load_json.py", line 28, in load_response
    if not response['data']['listByArea']:
KeyError: 'data'

During handling of the above exception, another exception occurred:

Traceback (most recent call last):
  File "load_json.py", line 28, in load_response
    if not response['data']['listByArea']:
KeyError: 'data'
2020-01-27 14:23:58,791 load_json.py[line:30] INFO json loaded at time 2020-01-27 14:23:58
2020-01-27 14:24:06,178 load_json.py[line:30] INFO json loaded at time 2020-01-27 14:24:06
2020-01-27 14:24:18,596 load_json.py[line:30] INFO json loaded at time 2020-01-27 14:24:18
2020-01-27 14:24:30,764 load_json.py[line:33] ERROR json load failed, waiting for around 15 seconds
2020-01-27 14:24:30,765 load_json.py[line:34] ERROR 'data'
Traceback (most recent call last):
  File "load_json.py", line 28, in load_response
    if not response['data']['listByArea']:
KeyError: 'data'
2020-01-27 14:24:49,938 load_json.py[line:33] ERROR json load failed, waiting for around 15 seconds
2020-01-27 14:24:49,938 load_json.py[line:34] ERROR 'data'
Traceback (most recent call last):
  File "load_json.py", line 28, in load_response
    if not response['data']['listByArea']:
KeyError: 'data'

During handling of the above exception, another exception occurred:

Traceback (most recent call last):
  File "load_json.py", line 28, in load_response
    if not response['data']['listByArea']:
KeyError: 'data'
2020-01-27 14:25:06,129 load_json.py[line:30] INFO json loaded at time 2020-01-27 14:25:06
2020-01-27 14:25:12,911 load_json.py[line:30] INFO json loaded at time 2020-01-27 14:25:12
2020-01-27 14:25:20,631 load_json.py[line:30] INFO json loaded at time 2020-01-27 14:25:20
2020-01-27 14:25:32,690 load_json.py[line:30] INFO json loaded at time 2020-01-27 14:25:32
2020-01-27 14:25:43,545 load_json.py[line:30] INFO json loaded at time 2020-01-27 14:25:43
2020-01-27 14:25:56,812 load_json.py[line:30] INFO json loaded at time 2020-01-27 14:25:56
2020-01-27 14:26:07,168 load_json.py[line:30] INFO json loaded at time 2020-01-27 14:26:07
2020-01-27 14:26:19,883 load_json.py[line:30] INFO json loaded at time 2020-01-27 14:26:19
2020-01-27 14:26:26,105 load_json.py[line:33] ERROR json load failed, waiting for around 15 seconds
2020-01-27 14:26:26,105 load_json.py[line:34] ERROR 'data'
Traceback (most recent call last):
  File "load_json.py", line 28, in load_response
    if not response['data']['listByArea']:
KeyError: 'data'
2020-01-27 14:26:43,640 load_json.py[line:30] INFO json loaded at time 2020-01-27 14:26:43
2020-01-27 14:26:55,572 load_json.py[line:33] ERROR json load failed, waiting for around 15 seconds
2020-01-27 14:26:55,573 load_json.py[line:34] ERROR 'data'
Traceback (most recent call last):
  File "load_json.py", line 28, in load_response
    if not response['data']['listByArea']:
KeyError: 'data'
2020-01-27 14:27:12,954 load_json.py[line:30] INFO json loaded at time 2020-01-27 14:27:12
2020-01-27 14:27:20,248 load_json.py[line:33] ERROR json load failed, waiting for around 15 seconds
2020-01-27 14:27:20,248 load_json.py[line:34] ERROR 'data'
Traceback (most recent call last):
  File "load_json.py", line 28, in load_response
    if not response['data']['listByArea']:
KeyError: 'data'
2020-01-27 14:27:36,780 load_json.py[line:30] INFO json loaded at time 2020-01-27 14:27:36
2020-01-27 14:27:47,539 load_json.py[line:30] INFO json loaded at time 2020-01-27 14:27:47
2020-01-27 14:28:02,991 load_json.py[line:30] INFO json loaded at time 2020-01-27 14:28:02
2020-01-27 14:28:13,706 load_json.py[line:30] INFO json loaded at time 2020-01-27 14:28:13
2020-01-27 14:28:28,191 load_json.py[line:33] ERROR json load failed, waiting for around 15 seconds
2020-01-27 14:28:28,191 load_json.py[line:34] ERROR 'data'
Traceback (most recent call last):
  File "load_json.py", line 28, in load_response
    if not response['data']['listByArea']:
KeyError: 'data'
2020-01-27 14:28:44,954 load_json.py[line:30] INFO json loaded at time 2020-01-27 14:28:44
2020-01-27 14:28:58,022 load_json.py[line:33] ERROR json load failed, waiting for around 15 seconds
2020-01-27 14:28:58,022 load_json.py[line:34] ERROR 'data'
Traceback (most recent call last):
  File "load_json.py", line 28, in load_response
    if not response['data']['listByArea']:
KeyError: 'data'
2020-01-27 14:29:17,802 load_json.py[line:33] ERROR json load failed, waiting for around 15 seconds
2020-01-27 14:29:17,802 load_json.py[line:34] ERROR 'data'
Traceback (most recent call last):
  File "load_json.py", line 28, in load_response
    if not response['data']['listByArea']:
KeyError: 'data'

During handling of the above exception, another exception occurred:

Traceback (most recent call last):
  File "load_json.py", line 28, in load_response
    if not response['data']['listByArea']:
KeyError: 'data'
2020-01-27 14:29:36,764 load_json.py[line:30] INFO json loaded at time 2020-01-27 14:29:36
2020-01-27 14:29:48,472 load_json.py[line:33] ERROR json load failed, waiting for around 15 seconds
2020-01-27 14:29:48,473 load_json.py[line:34] ERROR 'data'
Traceback (most recent call last):
  File "load_json.py", line 28, in load_response
    if not response['data']['listByArea']:
KeyError: 'data'
2020-01-27 14:30:05,305 load_json.py[line:30] INFO json loaded at time 2020-01-27 14:30:05
2020-01-27 14:30:18,288 load_json.py[line:30] INFO json loaded at time 2020-01-27 14:30:18
2020-01-27 14:30:26,300 load_json.py[line:30] INFO json loaded at time 2020-01-27 14:30:26
2020-01-27 14:30:40,789 load_json.py[line:30] INFO json loaded at time 2020-01-27 14:30:40
2020-01-27 14:30:54,777 load_json.py[line:33] ERROR json load failed, waiting for around 15 seconds
2020-01-27 14:30:54,777 load_json.py[line:34] ERROR 'data'
Traceback (most recent call last):
  File "load_json.py", line 28, in load_response
    if not response['data']['listByArea']:
KeyError: 'data'
2020-01-27 14:31:14,188 load_json.py[line:30] INFO json loaded at time 2020-01-27 14:31:14
2020-01-27 14:31:24,405 load_json.py[line:30] INFO json loaded at time 2020-01-27 14:31:24
2020-01-27 14:31:31,559 load_json.py[line:30] INFO json loaded at time 2020-01-27 14:31:31
2020-01-27 14:31:40,938 load_json.py[line:30] INFO json loaded at time 2020-01-27 14:31:40
2020-01-27 14:31:47,926 load_json.py[line:30] INFO json loaded at time 2020-01-27 14:31:47
2020-01-27 14:32:01,946 load_json.py[line:30] INFO json loaded at time 2020-01-27 14:32:01
2020-01-27 14:32:17,237 load_json.py[line:33] ERROR json load failed, waiting for around 15 seconds
2020-01-27 14:32:17,238 load_json.py[line:34] ERROR 'data'
Traceback (most recent call last):
  File "load_json.py", line 28, in load_response
    if not response['data']['listByArea']:
KeyError: 'data'
2020-01-27 14:32:37,394 load_json.py[line:30] INFO json loaded at time 2020-01-27 14:32:37
2020-01-27 14:32:43,903 load_json.py[line:30] INFO json loaded at time 2020-01-27 14:32:43
2020-01-27 14:32:55,488 load_json.py[line:30] INFO json loaded at time 2020-01-27 14:32:55
2020-01-27 14:33:11,527 load_json.py[line:30] INFO json loaded at time 2020-01-27 14:33:11
2020-01-27 14:33:24,782 load_json.py[line:33] ERROR json load failed, waiting for around 15 seconds
2020-01-27 14:33:24,782 load_json.py[line:34] ERROR 'data'
Traceback (most recent call last):
  File "load_json.py", line 28, in load_response
    if not response['data']['listByArea']:
KeyError: 'data'
2020-01-27 14:33:42,915 load_json.py[line:30] INFO json loaded at time 2020-01-27 14:33:42
2020-01-27 14:33:56,534 load_json.py[line:30] INFO json loaded at time 2020-01-27 14:33:56
2020-01-27 14:34:04,946 load_json.py[line:33] ERROR json load failed, waiting for around 15 seconds
2020-01-27 14:34:04,946 load_json.py[line:34] ERROR 'data'
Traceback (most recent call last):
  File "load_json.py", line 28, in load_response
    if not response['data']['listByArea']:
KeyError: 'data'
2020-01-27 14:34:22,588 load_json.py[line:33] ERROR json load failed, waiting for around 15 seconds
2020-01-27 14:34:22,588 load_json.py[line:34] ERROR 'data'
Traceback (most recent call last):
  File "load_json.py", line 28, in load_response
    if not response['data']['listByArea']:
KeyError: 'data'

During handling of the above exception, another exception occurred:

Traceback (most recent call last):
  File "load_json.py", line 28, in load_response
    if not response['data']['listByArea']:
KeyError: 'data'
2020-01-27 14:34:39,789 load_json.py[line:30] INFO json loaded at time 2020-01-27 14:34:39
2020-01-27 14:34:53,871 load_json.py[line:33] ERROR json load failed, waiting for around 15 seconds
2020-01-27 14:34:53,872 load_json.py[line:34] ERROR 'data'
Traceback (most recent call last):
  File "load_json.py", line 28, in load_response
    if not response['data']['listByArea']:
KeyError: 'data'
2020-01-27 14:35:12,626 load_json.py[line:30] INFO json loaded at time 2020-01-27 14:35:12
2020-01-27 14:35:24,941 load_json.py[line:33] ERROR json load failed, waiting for around 15 seconds
2020-01-27 14:35:24,941 load_json.py[line:34] ERROR 'data'
Traceback (most recent call last):
  File "load_json.py", line 28, in load_response
    if not response['data']['listByArea']:
KeyError: 'data'
2020-01-27 14:35:45,213 load_json.py[line:33] ERROR json load failed, waiting for around 15 seconds
2020-01-27 14:35:45,213 load_json.py[line:34] ERROR 'data'
Traceback (most recent call last):
  File "load_json.py", line 28, in load_response
    if not response['data']['listByArea']:
KeyError: 'data'

During handling of the above exception, another exception occurred:

Traceback (most recent call last):
  File "load_json.py", line 28, in load_response
    if not response['data']['listByArea']:
KeyError: 'data'
2020-01-27 14:36:04,030 load_json.py[line:30] INFO json loaded at time 2020-01-27 14:36:04
2020-01-27 14:36:15,536 load_json.py[line:33] ERROR json load failed, waiting for around 15 seconds
2020-01-27 14:36:15,537 load_json.py[line:34] ERROR 'data'
Traceback (most recent call last):
  File "load_json.py", line 28, in load_response
    if not response['data']['listByArea']:
KeyError: 'data'
2020-01-27 14:36:34,398 load_json.py[line:30] INFO json loaded at time 2020-01-27 14:36:34
2020-01-27 14:36:45,679 load_json.py[line:33] ERROR json load failed, waiting for around 15 seconds
2020-01-27 14:36:45,680 load_json.py[line:34] ERROR 'data'
Traceback (most recent call last):
  File "load_json.py", line 28, in load_response
    if not response['data']['listByArea']:
KeyError: 'data'
2020-01-27 14:37:03,658 load_json.py[line:30] INFO json loaded at time 2020-01-27 14:37:03
2020-01-27 14:37:12,291 load_json.py[line:33] ERROR json load failed, waiting for around 15 seconds
2020-01-27 14:37:12,291 load_json.py[line:34] ERROR 'data'
Traceback (most recent call last):
  File "load_json.py", line 28, in load_response
    if not response['data']['listByArea']:
KeyError: 'data'
2020-01-27 14:37:30,454 load_json.py[line:30] INFO json loaded at time 2020-01-27 14:37:30
2020-01-27 14:37:36,017 load_json.py[line:33] ERROR json load failed, waiting for around 15 seconds
2020-01-27 14:37:36,017 load_json.py[line:34] ERROR 'data'
Traceback (most recent call last):
  File "load_json.py", line 28, in load_response
    if not response['data']['listByArea']:
KeyError: 'data'
2020-01-27 14:37:56,280 load_json.py[line:30] INFO json loaded at time 2020-01-27 14:37:56
2020-01-27 14:38:06,099 load_json.py[line:33] ERROR json load failed, waiting for around 15 seconds
2020-01-27 14:38:06,100 load_json.py[line:34] ERROR 'data'
Traceback (most recent call last):
  File "load_json.py", line 28, in load_response
    if not response['data']['listByArea']:
KeyError: 'data'
2020-01-27 14:38:26,125 load_json.py[line:30] INFO json loaded at time 2020-01-27 14:38:26
2020-01-27 14:38:34,035 load_json.py[line:30] INFO json loaded at time 2020-01-27 14:38:34
2020-01-27 14:38:48,163 load_json.py[line:33] ERROR json load failed, waiting for around 15 seconds
2020-01-27 14:38:48,163 load_json.py[line:34] ERROR 'data'
Traceback (most recent call last):
  File "load_json.py", line 28, in load_response
    if not response['data']['listByArea']:
KeyError: 'data'
2020-01-27 14:39:06,051 load_json.py[line:33] ERROR json load failed, waiting for around 15 seconds
2020-01-27 14:39:06,051 load_json.py[line:34] ERROR 'data'
Traceback (most recent call last):
  File "load_json.py", line 28, in load_response
    if not response['data']['listByArea']:
KeyError: 'data'

During handling of the above exception, another exception occurred:

Traceback (most recent call last):
  File "load_json.py", line 28, in load_response
    if not response['data']['listByArea']:
KeyError: 'data'
2020-01-27 14:39:26,878 load_json.py[line:30] INFO json loaded at time 2020-01-27 14:39:26
2020-01-27 14:39:33,583 load_json.py[line:30] INFO json loaded at time 2020-01-27 14:39:33
2020-01-27 14:39:45,812 load_json.py[line:33] ERROR json load failed, waiting for around 15 seconds
2020-01-27 14:39:45,812 load_json.py[line:34] ERROR 'data'
Traceback (most recent call last):
  File "load_json.py", line 28, in load_response
    if not response['data']['listByArea']:
KeyError: 'data'
2020-01-27 14:40:05,485 load_json.py[line:30] INFO json loaded at time 2020-01-27 14:40:05
2020-01-27 14:40:16,269 load_json.py[line:30] INFO json loaded at time 2020-01-27 14:40:16
2020-01-27 14:40:22,466 load_json.py[line:33] ERROR json load failed, waiting for around 15 seconds
2020-01-27 14:40:22,467 load_json.py[line:34] ERROR 'data'
Traceback (most recent call last):
  File "load_json.py", line 28, in load_response
    if not response['data']['listByArea']:
KeyError: 'data'
2020-01-27 14:40:40,336 load_json.py[line:30] INFO json loaded at time 2020-01-27 14:40:40
2020-01-27 14:40:48,923 load_json.py[line:33] ERROR json load failed, waiting for around 15 seconds
2020-01-27 14:40:48,923 load_json.py[line:34] ERROR 'data'
Traceback (most recent call last):
  File "load_json.py", line 28, in load_response
    if not response['data']['listByArea']:
KeyError: 'data'
2020-01-27 14:41:09,014 load_json.py[line:30] INFO json loaded at time 2020-01-27 14:41:09
2020-01-27 14:41:16,988 load_json.py[line:30] INFO json loaded at time 2020-01-27 14:41:16
2020-01-27 14:41:28,582 load_json.py[line:30] INFO json loaded at time 2020-01-27 14:41:28
2020-01-27 14:41:40,120 load_json.py[line:30] INFO json loaded at time 2020-01-27 14:41:40
2020-01-27 14:41:51,561 load_json.py[line:33] ERROR json load failed, waiting for around 15 seconds
2020-01-27 14:41:51,561 load_json.py[line:34] ERROR 'data'
Traceback (most recent call last):
  File "load_json.py", line 28, in load_response
    if not response['data']['listByArea']:
KeyError: 'data'
2020-01-27 14:42:09,375 load_json.py[line:33] ERROR json load failed, waiting for around 15 seconds
2020-01-27 14:42:09,376 load_json.py[line:34] ERROR 'data'
Traceback (most recent call last):
  File "load_json.py", line 28, in load_response
    if not response['data']['listByArea']:
KeyError: 'data'

During handling of the above exception, another exception occurred:

Traceback (most recent call last):
  File "load_json.py", line 28, in load_response
    if not response['data']['listByArea']:
KeyError: 'data'
2020-01-27 14:42:25,645 load_json.py[line:30] INFO json loaded at time 2020-01-27 14:42:25
2020-01-27 14:42:26,447 load_json.py[line:30] INFO json loaded at time 2020-01-27 14:42:26
2020-01-27 14:42:41,654 load_json.py[line:33] ERROR json load failed, waiting for around 15 seconds
2020-01-27 14:42:41,654 load_json.py[line:34] ERROR 'data'
Traceback (most recent call last):
  File "load_json.py", line 28, in load_response
    if not response['data']['listByArea']:
KeyError: 'data'
2020-01-27 14:42:58,995 load_json.py[line:30] INFO json loaded at time 2020-01-27 14:42:58
2020-01-27 14:43:08,629 load_json.py[line:30] INFO json loaded at time 2020-01-27 14:43:08
2020-01-27 14:43:09,310 load_json.py[line:30] INFO json loaded at time 2020-01-27 14:43:09
2020-01-27 14:43:24,058 load_json.py[line:30] INFO json loaded at time 2020-01-27 14:43:24
2020-01-27 14:43:30,192 load_json.py[line:33] ERROR json load failed, waiting for around 15 seconds
2020-01-27 14:43:30,193 load_json.py[line:34] ERROR 'data'
Traceback (most recent call last):
  File "load_json.py", line 28, in load_response
    if not response['data']['listByArea']:
KeyError: 'data'
2020-01-27 14:43:49,068 load_json.py[line:30] INFO json loaded at time 2020-01-27 14:43:49
2020-01-27 14:43:59,624 load_json.py[line:30] INFO json loaded at time 2020-01-27 14:43:59
2020-01-27 14:44:00,611 load_json.py[line:30] INFO json loaded at time 2020-01-27 14:44:00
2020-01-27 14:44:00,612 load_json.py[line:91] INFO data constructed
2020-01-27 14:44:00,612 load_json.py[line:102] INFO data updated at 1580107440.611981
2020-01-27 14:44:12,207 load_json.py[line:30] INFO json loaded at time 2020-01-27 14:44:12
2020-01-27 14:44:25,031 load_json.py[line:30] INFO json loaded at time 2020-01-27 14:44:25
2020-01-27 14:44:36,200 load_json.py[line:30] INFO json loaded at time 2020-01-27 14:44:36
2020-01-27 14:44:43,076 load_json.py[line:30] INFO json loaded at time 2020-01-27 14:44:43
2020-01-27 14:44:55,587 load_json.py[line:30] INFO json loaded at time 2020-01-27 14:44:55
2020-01-27 14:45:07,804 load_json.py[line:33] ERROR json load failed, waiting for around 15 seconds
2020-01-27 14:45:07,804 load_json.py[line:34] ERROR 'data'
Traceback (most recent call last):
  File "load_json.py", line 28, in load_response
    if not response['data']['listByArea']:
KeyError: 'data'
2020-01-27 14:45:25,480 load_json.py[line:33] ERROR json load failed, waiting for around 15 seconds
2020-01-27 14:45:25,480 load_json.py[line:34] ERROR 'data'
Traceback (most recent call last):
  File "load_json.py", line 28, in load_response
    if not response['data']['listByArea']:
KeyError: 'data'

During handling of the above exception, another exception occurred:

Traceback (most recent call last):
  File "load_json.py", line 28, in load_response
    if not response['data']['listByArea']:
KeyError: 'data'
2020-01-27 14:45:43,839 load_json.py[line:30] INFO json loaded at time 2020-01-27 14:45:43
2020-01-27 14:45:58,768 load_json.py[line:30] INFO json loaded at time 2020-01-27 14:45:58
2020-01-27 14:46:06,010 load_json.py[line:33] ERROR json load failed, waiting for around 15 seconds
2020-01-27 14:46:06,010 load_json.py[line:34] ERROR 'data'
Traceback (most recent call last):
  File "load_json.py", line 28, in load_response
    if not response['data']['listByArea']:
KeyError: 'data'
2020-01-27 14:46:26,144 load_json.py[line:33] ERROR json load failed, waiting for around 15 seconds
2020-01-27 14:46:26,144 load_json.py[line:34] ERROR 'data'
Traceback (most recent call last):
  File "load_json.py", line 28, in load_response
    if not response['data']['listByArea']:
KeyError: 'data'

During handling of the above exception, another exception occurred:

Traceback (most recent call last):
  File "load_json.py", line 28, in load_response
    if not response['data']['listByArea']:
KeyError: 'data'
2020-01-27 14:46:41,989 load_json.py[line:30] INFO json loaded at time 2020-01-27 14:46:41
2020-01-27 14:46:49,714 load_json.py[line:33] ERROR json load failed, waiting for around 15 seconds
2020-01-27 14:46:49,714 load_json.py[line:34] ERROR 'data'
Traceback (most recent call last):
  File "load_json.py", line 28, in load_response
    if not response['data']['listByArea']:
KeyError: 'data'
2020-01-27 14:47:09,860 load_json.py[line:30] INFO json loaded at time 2020-01-27 14:47:09
2020-01-27 14:47:22,133 load_json.py[line:30] INFO json loaded at time 2020-01-27 14:47:22
2020-01-27 14:47:35,785 load_json.py[line:33] ERROR json load failed, waiting for around 15 seconds
2020-01-27 14:47:35,785 load_json.py[line:34] ERROR 'data'
Traceback (most recent call last):
  File "load_json.py", line 28, in load_response
    if not response['data']['listByArea']:
KeyError: 'data'
2020-01-27 14:47:51,865 load_json.py[line:33] ERROR json load failed, waiting for around 15 seconds
2020-01-27 14:47:51,865 load_json.py[line:34] ERROR 'data'
Traceback (most recent call last):
  File "load_json.py", line 28, in load_response
    if not response['data']['listByArea']:
KeyError: 'data'

During handling of the above exception, another exception occurred:

Traceback (most recent call last):
  File "load_json.py", line 28, in load_response
    if not response['data']['listByArea']:
KeyError: 'data'
2020-01-27 14:48:11,805 load_json.py[line:30] INFO json loaded at time 2020-01-27 14:48:11
2020-01-27 14:48:25,519 load_json.py[line:30] INFO json loaded at time 2020-01-27 14:48:25
2020-01-27 14:48:38,676 load_json.py[line:33] ERROR json load failed, waiting for around 15 seconds
2020-01-27 14:48:38,677 load_json.py[line:34] ERROR 'data'
Traceback (most recent call last):
  File "load_json.py", line 28, in load_response
    if not response['data']['listByArea']:
KeyError: 'data'
2020-01-27 14:48:56,729 load_json.py[line:30] INFO json loaded at time 2020-01-27 14:48:56
2020-01-27 14:49:07,700 load_json.py[line:30] INFO json loaded at time 2020-01-27 14:49:07
2020-01-27 14:49:22,058 load_json.py[line:30] INFO json loaded at time 2020-01-27 14:49:22
2020-01-27 14:49:35,992 load_json.py[line:33] ERROR json load failed, waiting for around 15 seconds
2020-01-27 14:49:35,992 load_json.py[line:34] ERROR 'data'
Traceback (most recent call last):
  File "load_json.py", line 28, in load_response
    if not response['data']['listByArea']:
KeyError: 'data'
2020-01-27 14:49:55,823 load_json.py[line:30] INFO json loaded at time 2020-01-27 14:49:55
2020-01-27 14:50:09,621 load_json.py[line:30] INFO json loaded at time 2020-01-27 14:50:09
2020-01-27 14:50:21,880 load_json.py[line:30] INFO json loaded at time 2020-01-27 14:50:21
2020-01-27 14:50:33,180 load_json.py[line:30] INFO json loaded at time 2020-01-27 14:50:33
2020-01-27 14:50:39,504 load_json.py[line:33] ERROR json load failed, waiting for around 15 seconds
2020-01-27 14:50:39,505 load_json.py[line:34] ERROR 'data'
Traceback (most recent call last):
  File "load_json.py", line 28, in load_response
    if not response['data']['listByArea']:
KeyError: 'data'
2020-01-27 14:50:57,712 load_json.py[line:30] INFO json loaded at time 2020-01-27 14:50:57
2020-01-27 14:51:03,585 load_json.py[line:33] ERROR json load failed, waiting for around 15 seconds
2020-01-27 14:51:03,586 load_json.py[line:34] ERROR 'data'
Traceback (most recent call last):
  File "load_json.py", line 28, in load_response
    if not response['data']['listByArea']:
KeyError: 'data'
2020-01-27 14:51:20,841 load_json.py[line:30] INFO json loaded at time 2020-01-27 14:51:20
2020-01-27 14:51:34,977 load_json.py[line:30] INFO json loaded at time 2020-01-27 14:51:34
2020-01-27 14:51:46,158 load_json.py[line:30] INFO json loaded at time 2020-01-27 14:51:46
2020-01-27 14:51:58,039 load_json.py[line:30] INFO json loaded at time 2020-01-27 14:51:58
2020-01-27 14:52:04,017 load_json.py[line:30] INFO json loaded at time 2020-01-27 14:52:04
2020-01-27 14:52:18,400 load_json.py[line:30] INFO json loaded at time 2020-01-27 14:52:18
2020-01-27 14:52:31,595 load_json.py[line:30] INFO json loaded at time 2020-01-27 14:52:31
2020-01-27 14:52:42,943 load_json.py[line:30] INFO json loaded at time 2020-01-27 14:52:42
2020-01-27 14:52:50,621 load_json.py[line:30] INFO json loaded at time 2020-01-27 14:52:50
2020-01-27 14:53:02,878 load_json.py[line:33] ERROR json load failed, waiting for around 15 seconds
2020-01-27 14:53:02,879 load_json.py[line:34] ERROR 'data'
Traceback (most recent call last):
  File "load_json.py", line 28, in load_response
    if not response['data']['listByArea']:
KeyError: 'data'
2020-01-27 14:53:20,379 load_json.py[line:30] INFO json loaded at time 2020-01-27 14:53:20
2020-01-27 14:53:36,374 load_json.py[line:30] INFO json loaded at time 2020-01-27 14:53:36
2020-01-27 14:53:49,761 load_json.py[line:30] INFO json loaded at time 2020-01-27 14:53:49
2020-01-27 14:54:04,648 load_json.py[line:30] INFO json loaded at time 2020-01-27 14:54:04
2020-01-27 14:54:15,656 load_json.py[line:30] INFO json loaded at time 2020-01-27 14:54:15
2020-01-27 14:54:31,619 load_json.py[line:30] INFO json loaded at time 2020-01-27 14:54:31
2020-01-27 14:54:44,919 load_json.py[line:30] INFO json loaded at time 2020-01-27 14:54:44
2020-01-27 14:54:58,131 load_json.py[line:30] INFO json loaded at time 2020-01-27 14:54:58
2020-01-27 14:55:09,740 load_json.py[line:30] INFO json loaded at time 2020-01-27 14:55:09
2020-01-27 14:55:16,452 load_json.py[line:30] INFO json loaded at time 2020-01-27 14:55:16
2020-01-27 14:55:24,378 load_json.py[line:33] ERROR json load failed, waiting for around 15 seconds
2020-01-27 14:55:24,378 load_json.py[line:34] ERROR 'data'
Traceback (most recent call last):
  File "load_json.py", line 28, in load_response
    if not response['data']['listByArea']:
KeyError: 'data'
2020-01-27 14:55:42,265 load_json.py[line:30] INFO json loaded at time 2020-01-27 14:55:42
2020-01-27 14:55:55,669 load_json.py[line:30] INFO json loaded at time 2020-01-27 14:55:55
2020-01-27 14:56:05,140 load_json.py[line:30] INFO json loaded at time 2020-01-27 14:56:05
2020-01-27 14:56:17,059 load_json.py[line:30] INFO json loaded at time 2020-01-27 14:56:17
2020-01-27 14:56:28,774 load_json.py[line:30] INFO json loaded at time 2020-01-27 14:56:28
2020-01-27 14:56:42,610 load_json.py[line:30] INFO json loaded at time 2020-01-27 14:56:42
2020-01-27 14:56:55,789 load_json.py[line:30] INFO json loaded at time 2020-01-27 14:56:55
2020-01-27 14:57:03,937 load_json.py[line:30] INFO json loaded at time 2020-01-27 14:57:03
2020-01-27 14:57:11,331 load_json.py[line:33] ERROR json load failed, waiting for around 15 seconds
2020-01-27 14:57:11,332 load_json.py[line:34] ERROR 'data'
Traceback (most recent call last):
  File "load_json.py", line 28, in load_response
    if not response['data']['listByArea']:
KeyError: 'data'
2020-01-27 14:57:29,609 load_json.py[line:30] INFO json loaded at time 2020-01-27 14:57:29
2020-01-27 14:57:30,504 load_json.py[line:30] INFO json loaded at time 2020-01-27 14:57:30
2020-01-27 14:57:30,505 load_json.py[line:91] INFO data constructed
2020-01-27 14:57:30,505 load_json.py[line:102] INFO data updated at 1580108250.505304
2020-01-27 14:57:41,299 load_json.py[line:30] INFO json loaded at time 2020-01-27 14:57:41
2020-01-27 14:57:51,367 load_json.py[line:33] ERROR json load failed, waiting for around 15 seconds
2020-01-27 14:57:51,367 load_json.py[line:34] ERROR 'data'
Traceback (most recent call last):
  File "load_json.py", line 28, in load_response
    if not response['data']['listByArea']:
KeyError: 'data'
2020-01-27 14:58:09,842 load_json.py[line:33] ERROR json load failed, waiting for around 15 seconds
2020-01-27 14:58:09,843 load_json.py[line:34] ERROR 'data'
Traceback (most recent call last):
  File "load_json.py", line 28, in load_response
    if not response['data']['listByArea']:
KeyError: 'data'

During handling of the above exception, another exception occurred:

Traceback (most recent call last):
  File "load_json.py", line 28, in load_response
    if not response['data']['listByArea']:
KeyError: 'data'
2020-01-27 14:58:28,109 load_json.py[line:30] INFO json loaded at time 2020-01-27 14:58:28
2020-01-27 14:58:36,198 load_json.py[line:30] INFO json loaded at time 2020-01-27 14:58:36
2020-01-27 14:58:50,130 load_json.py[line:33] ERROR json load failed, waiting for around 15 seconds
2020-01-27 14:58:50,130 load_json.py[line:34] ERROR 'data'
Traceback (most recent call last):
  File "load_json.py", line 28, in load_response
    if not response['data']['listByArea']:
KeyError: 'data'
2020-01-27 14:59:06,336 load_json.py[line:33] ERROR json load failed, waiting for around 15 seconds
2020-01-27 14:59:06,337 load_json.py[line:34] ERROR 'data'
Traceback (most recent call last):
  File "load_json.py", line 28, in load_response
    if not response['data']['listByArea']:
KeyError: 'data'

During handling of the above exception, another exception occurred:

Traceback (most recent call last):
  File "load_json.py", line 28, in load_response
    if not response['data']['listByArea']:
KeyError: 'data'
2020-01-27 14:59:23,402 load_json.py[line:30] INFO json loaded at time 2020-01-27 14:59:23
2020-01-27 14:59:30,775 load_json.py[line:30] INFO json loaded at time 2020-01-27 14:59:30
2020-01-27 14:59:40,015 load_json.py[line:30] INFO json loaded at time 2020-01-27 14:59:40
2020-01-27 14:59:47,710 load_json.py[line:30] INFO json loaded at time 2020-01-27 14:59:47
2020-01-27 14:59:58,040 load_json.py[line:30] INFO json loaded at time 2020-01-27 14:59:58
2020-01-27 15:00:05,379 load_json.py[line:30] INFO json loaded at time 2020-01-27 15:00:05
2020-01-27 15:00:14,009 load_json.py[line:30] INFO json loaded at time 2020-01-27 15:00:14
2020-01-27 15:00:24,300 load_json.py[line:33] ERROR json load failed, waiting for around 15 seconds
2020-01-27 15:00:24,300 load_json.py[line:34] ERROR 'data'
Traceback (most recent call last):
  File "load_json.py", line 28, in load_response
    if not response['data']['listByArea']:
KeyError: 'data'
2020-01-27 15:00:44,698 load_json.py[line:30] INFO json loaded at time 2020-01-27 15:00:44
2020-01-27 15:00:52,556 load_json.py[line:30] INFO json loaded at time 2020-01-27 15:00:52
2020-01-27 15:01:03,753 load_json.py[line:33] ERROR json load failed, waiting for around 15 seconds
2020-01-27 15:01:03,753 load_json.py[line:34] ERROR 'data'
Traceback (most recent call last):
  File "load_json.py", line 28, in load_response
    if not response['data']['listByArea']:
KeyError: 'data'
2020-01-27 15:01:23,151 load_json.py[line:30] INFO json loaded at time 2020-01-27 15:01:23
2020-01-27 15:01:33,659 load_json.py[line:30] INFO json loaded at time 2020-01-27 15:01:33
2020-01-27 15:01:41,452 load_json.py[line:30] INFO json loaded at time 2020-01-27 15:01:41
2020-01-27 15:01:49,668 load_json.py[line:30] INFO json loaded at time 2020-01-27 15:01:49
2020-01-27 15:02:02,783 load_json.py[line:30] INFO json loaded at time 2020-01-27 15:02:02
2020-01-27 15:02:10,930 load_json.py[line:30] INFO json loaded at time 2020-01-27 15:02:10
2020-01-27 15:02:21,943 load_json.py[line:30] INFO json loaded at time 2020-01-27 15:02:21
2020-01-27 15:02:31,092 load_json.py[line:30] INFO json loaded at time 2020-01-27 15:02:31
2020-01-27 15:02:43,926 load_json.py[line:33] ERROR json load failed, waiting for around 15 seconds
2020-01-27 15:02:43,926 load_json.py[line:34] ERROR 'data'
Traceback (most recent call last):
  File "load_json.py", line 28, in load_response
    if not response['data']['listByArea']:
KeyError: 'data'
2020-01-27 15:03:04,460 load_json.py[line:30] INFO json loaded at time 2020-01-27 15:03:04
2020-01-27 15:03:19,105 load_json.py[line:30] INFO json loaded at time 2020-01-27 15:03:19
2020-01-27 15:03:29,625 load_json.py[line:30] INFO json loaded at time 2020-01-27 15:03:29
2020-01-27 15:03:38,259 load_json.py[line:30] INFO json loaded at time 2020-01-27 15:03:38
2020-01-27 15:03:45,546 load_json.py[line:33] ERROR json load failed, waiting for around 15 seconds
2020-01-27 15:03:45,546 load_json.py[line:34] ERROR 'data'
Traceback (most recent call last):
  File "load_json.py", line 28, in load_response
    if not response['data']['listByArea']:
KeyError: 'data'
2020-01-27 15:04:03,458 load_json.py[line:33] ERROR json load failed, waiting for around 15 seconds
2020-01-27 15:04:03,458 load_json.py[line:34] ERROR 'data'
Traceback (most recent call last):
  File "load_json.py", line 28, in load_response
    if not response['data']['listByArea']:
KeyError: 'data'

During handling of the above exception, another exception occurred:

Traceback (most recent call last):
  File "load_json.py", line 28, in load_response
    if not response['data']['listByArea']:
KeyError: 'data'
2020-01-27 15:04:22,593 load_json.py[line:33] ERROR json load failed, waiting for around 15 seconds
2020-01-27 15:04:22,593 load_json.py[line:34] ERROR 'data'
Traceback (most recent call last):
  File "load_json.py", line 28, in load_response
    if not response['data']['listByArea']:
KeyError: 'data'

During handling of the above exception, another exception occurred:

Traceback (most recent call last):
  File "load_json.py", line 28, in load_response
    if not response['data']['listByArea']:
KeyError: 'data'

During handling of the above exception, another exception occurred:

Traceback (most recent call last):
  File "load_json.py", line 28, in load_response
    if not response['data']['listByArea']:
KeyError: 'data'
2020-01-27 15:04:41,379 load_json.py[line:33] ERROR json load failed, waiting for around 15 seconds
2020-01-27 15:04:41,380 load_json.py[line:34] ERROR 'data'
Traceback (most recent call last):
  File "load_json.py", line 28, in load_response
    if not response['data']['listByArea']:
KeyError: 'data'

During handling of the above exception, another exception occurred:

Traceback (most recent call last):
  File "load_json.py", line 28, in load_response
    if not response['data']['listByArea']:
KeyError: 'data'

During handling of the above exception, another exception occurred:

Traceback (most recent call last):
  File "load_json.py", line 28, in load_response
    if not response['data']['listByArea']:
KeyError: 'data'

During handling of the above exception, another exception occurred:

Traceback (most recent call last):
  File "load_json.py", line 28, in load_response
    if not response['data']['listByArea']:
KeyError: 'data'
2020-01-27 15:05:00,641 load_json.py[line:33] ERROR json load failed, waiting for around 15 seconds
2020-01-27 15:05:00,642 load_json.py[line:34] ERROR 'data'
Traceback (most recent call last):
  File "load_json.py", line 28, in load_response
    if not response['data']['listByArea']:
KeyError: 'data'

During handling of the above exception, another exception occurred:

Traceback (most recent call last):
  File "load_json.py", line 28, in load_response
    if not response['data']['listByArea']:
KeyError: 'data'

During handling of the above exception, another exception occurred:

Traceback (most recent call last):
  File "load_json.py", line 28, in load_response
    if not response['data']['listByArea']:
KeyError: 'data'

During handling of the above exception, another exception occurred:

Traceback (most recent call last):
  File "load_json.py", line 28, in load_response
    if not response['data']['listByArea']:
KeyError: 'data'

During handling of the above exception, another exception occurred:

Traceback (most recent call last):
  File "load_json.py", line 28, in load_response
    if not response['data']['listByArea']:
KeyError: 'data'
2020-01-27 15:05:18,615 load_json.py[line:30] INFO json loaded at time 2020-01-27 15:05:18
2020-01-27 15:05:28,686 load_json.py[line:33] ERROR json load failed, waiting for around 15 seconds
2020-01-27 15:05:28,686 load_json.py[line:34] ERROR 'data'
Traceback (most recent call last):
  File "load_json.py", line 28, in load_response
    if not response['data']['listByArea']:
KeyError: 'data'
2020-01-27 15:05:46,000 load_json.py[line:30] INFO json loaded at time 2020-01-27 15:05:46
2020-01-27 15:05:55,775 load_json.py[line:30] INFO json loaded at time 2020-01-27 15:05:55
2020-01-27 15:06:08,910 load_json.py[line:33] ERROR json load failed, waiting for around 15 seconds
2020-01-27 15:06:08,910 load_json.py[line:34] ERROR 'data'
Traceback (most recent call last):
  File "load_json.py", line 28, in load_response
    if not response['data']['listByArea']:
KeyError: 'data'
2020-01-27 15:06:27,381 load_json.py[line:30] INFO json loaded at time 2020-01-27 15:06:27
2020-01-27 15:06:34,974 load_json.py[line:30] INFO json loaded at time 2020-01-27 15:06:34
2020-01-27 15:06:43,105 load_json.py[line:30] INFO json loaded at time 2020-01-27 15:06:43
2020-01-27 15:06:49,070 load_json.py[line:33] ERROR json load failed, waiting for around 15 seconds
2020-01-27 15:06:49,070 load_json.py[line:34] ERROR 'data'
Traceback (most recent call last):
  File "load_json.py", line 28, in load_response
    if not response['data']['listByArea']:
KeyError: 'data'
2020-01-27 15:07:09,635 load_json.py[line:30] INFO json loaded at time 2020-01-27 15:07:09
2020-01-27 15:07:15,641 load_json.py[line:33] ERROR json load failed, waiting for around 15 seconds
2020-01-27 15:07:15,641 load_json.py[line:34] ERROR 'data'
Traceback (most recent call last):
  File "load_json.py", line 28, in load_response
    if not response['data']['listByArea']:
KeyError: 'data'
2020-01-27 15:07:32,992 load_json.py[line:33] ERROR json load failed, waiting for around 15 seconds
2020-01-27 15:07:32,993 load_json.py[line:34] ERROR 'data'
Traceback (most recent call last):
  File "load_json.py", line 28, in load_response
    if not response['data']['listByArea']:
KeyError: 'data'

During handling of the above exception, another exception occurred:

Traceback (most recent call last):
  File "load_json.py", line 28, in load_response
    if not response['data']['listByArea']:
KeyError: 'data'
2020-01-27 15:07:50,423 load_json.py[line:30] INFO json loaded at time 2020-01-27 15:07:50
2020-01-27 15:07:59,630 load_json.py[line:30] INFO json loaded at time 2020-01-27 15:07:59
2020-01-27 15:08:10,480 load_json.py[line:30] INFO json loaded at time 2020-01-27 15:08:10
2020-01-27 15:08:24,166 load_json.py[line:30] INFO json loaded at time 2020-01-27 15:08:24
2020-01-27 15:08:37,336 load_json.py[line:30] INFO json loaded at time 2020-01-27 15:08:37
2020-01-27 15:08:52,188 load_json.py[line:33] ERROR json load failed, waiting for around 15 seconds
2020-01-27 15:08:52,188 load_json.py[line:34] ERROR 'data'
Traceback (most recent call last):
  File "load_json.py", line 28, in load_response
    if not response['data']['listByArea']:
KeyError: 'data'
2020-01-27 15:09:10,708 load_json.py[line:33] ERROR json load failed, waiting for around 15 seconds
2020-01-27 15:09:10,708 load_json.py[line:34] ERROR 'data'
Traceback (most recent call last):
  File "load_json.py", line 28, in load_response
    if not response['data']['listByArea']:
KeyError: 'data'

During handling of the above exception, another exception occurred:

Traceback (most recent call last):
  File "load_json.py", line 28, in load_response
    if not response['data']['listByArea']:
KeyError: 'data'
2020-01-27 15:09:32,803 load_json.py[line:30] INFO json loaded at time 2020-01-27 15:09:32
2020-01-27 15:09:40,024 load_json.py[line:33] ERROR json load failed, waiting for around 15 seconds
2020-01-27 15:09:40,024 load_json.py[line:34] ERROR 'data'
Traceback (most recent call last):
  File "load_json.py", line 28, in load_response
    if not response['data']['listByArea']:
KeyError: 'data'
2020-01-27 15:09:59,841 load_json.py[line:30] INFO json loaded at time 2020-01-27 15:09:59
2020-01-27 15:10:05,989 load_json.py[line:30] INFO json loaded at time 2020-01-27 15:10:05
2020-01-27 15:10:14,125 load_json.py[line:33] ERROR json load failed, waiting for around 15 seconds
2020-01-27 15:10:14,125 load_json.py[line:34] ERROR 'data'
Traceback (most recent call last):
  File "load_json.py", line 28, in load_response
    if not response['data']['listByArea']:
KeyError: 'data'
2020-01-27 15:10:33,880 load_json.py[line:30] INFO json loaded at time 2020-01-27 15:10:33
2020-01-27 15:10:44,674 load_json.py[line:30] INFO json loaded at time 2020-01-27 15:10:44
2020-01-27 15:10:56,656 load_json.py[line:30] INFO json loaded at time 2020-01-27 15:10:56
2020-01-27 15:11:08,911 load_json.py[line:30] INFO json loaded at time 2020-01-27 15:11:08
2020-01-27 15:11:20,443 load_json.py[line:33] ERROR json load failed, waiting for around 15 seconds
2020-01-27 15:11:20,443 load_json.py[line:34] ERROR 'data'
Traceback (most recent call last):
  File "load_json.py", line 28, in load_response
    if not response['data']['listByArea']:
KeyError: 'data'
2020-01-27 15:11:37,787 load_json.py[line:33] ERROR json load failed, waiting for around 15 seconds
2020-01-27 15:11:37,788 load_json.py[line:34] ERROR 'data'
Traceback (most recent call last):
  File "load_json.py", line 28, in load_response
    if not response['data']['listByArea']:
KeyError: 'data'

During handling of the above exception, another exception occurred:

Traceback (most recent call last):
  File "load_json.py", line 28, in load_response
    if not response['data']['listByArea']:
KeyError: 'data'
2020-01-27 15:11:53,671 load_json.py[line:33] ERROR json load failed, waiting for around 15 seconds
2020-01-27 15:11:53,672 load_json.py[line:34] ERROR 'data'
Traceback (most recent call last):
  File "load_json.py", line 28, in load_response
    if not response['data']['listByArea']:
KeyError: 'data'

During handling of the above exception, another exception occurred:

Traceback (most recent call last):
  File "load_json.py", line 28, in load_response
    if not response['data']['listByArea']:
KeyError: 'data'

During handling of the above exception, another exception occurred:

Traceback (most recent call last):
  File "load_json.py", line 28, in load_response
    if not response['data']['listByArea']:
KeyError: 'data'
2020-01-27 15:12:13,155 load_json.py[line:30] INFO json loaded at time 2020-01-27 15:12:13
2020-01-27 15:12:28,005 load_json.py[line:30] INFO json loaded at time 2020-01-27 15:12:28
2020-01-27 15:12:41,335 load_json.py[line:30] INFO json loaded at time 2020-01-27 15:12:41
2020-01-27 15:12:54,349 load_json.py[line:30] INFO json loaded at time 2020-01-27 15:12:54
2020-01-27 15:13:08,933 load_json.py[line:30] INFO json loaded at time 2020-01-27 15:13:08
2020-01-27 15:13:18,788 load_json.py[line:30] INFO json loaded at time 2020-01-27 15:13:18
2020-01-27 15:13:29,443 load_json.py[line:30] INFO json loaded at time 2020-01-27 15:13:29
2020-01-27 15:13:35,976 load_json.py[line:30] INFO json loaded at time 2020-01-27 15:13:35
2020-01-27 15:13:50,477 load_json.py[line:30] INFO json loaded at time 2020-01-27 15:13:50
2020-01-27 15:14:01,793 load_json.py[line:30] INFO json loaded at time 2020-01-27 15:14:01
2020-01-27 15:14:10,756 load_json.py[line:33] ERROR json load failed, waiting for around 15 seconds
2020-01-27 15:14:10,756 load_json.py[line:34] ERROR 'data'
Traceback (most recent call last):
  File "load_json.py", line 28, in load_response
    if not response['data']['listByArea']:
KeyError: 'data'
2020-01-27 15:14:26,993 load_json.py[line:30] INFO json loaded at time 2020-01-27 15:14:26
2020-01-27 15:14:37,629 load_json.py[line:30] INFO json loaded at time 2020-01-27 15:14:37
2020-01-27 15:14:52,925 load_json.py[line:30] INFO json loaded at time 2020-01-27 15:14:52
2020-01-27 15:15:00,549 load_json.py[line:30] INFO json loaded at time 2020-01-27 15:15:00
2020-01-27 15:15:00,930 load_json.py[line:33] ERROR json load failed, waiting for around 15 seconds
2020-01-27 15:15:00,931 load_json.py[line:34] ERROR 'data'
Traceback (most recent call last):
  File "load_json.py", line 28, in load_response
    if not response['data']['listByArea']:
KeyError: 'data'
2020-01-27 15:15:18,727 load_json.py[line:33] ERROR json load failed, waiting for around 15 seconds
2020-01-27 15:15:18,727 load_json.py[line:34] ERROR 'data'
Traceback (most recent call last):
  File "load_json.py", line 28, in load_response
    if not response['data']['listByArea']:
KeyError: 'data'

During handling of the above exception, another exception occurred:

Traceback (most recent call last):
  File "load_json.py", line 28, in load_response
    if not response['data']['listByArea']:
KeyError: 'data'
2020-01-27 15:15:34,851 load_json.py[line:30] INFO json loaded at time 2020-01-27 15:15:34
2020-01-27 15:15:34,852 load_json.py[line:91] INFO data constructed
2020-01-27 15:15:34,853 load_json.py[line:102] INFO data updated at 1580109334.8523252
2020-01-27 15:15:48,037 load_json.py[line:30] INFO json loaded at time 2020-01-27 15:15:48
2020-01-27 15:15:48,708 load_json.py[line:30] INFO json loaded at time 2020-01-27 15:15:48
2020-01-27 15:15:48,709 load_json.py[line:91] INFO data constructed
2020-01-27 15:15:48,709 load_json.py[line:102] INFO data updated at 1580109348.7091177
2020-01-27 15:16:01,706 load_json.py[line:30] INFO json loaded at time 2020-01-27 15:16:01
2020-01-27 15:16:02,560 load_json.py[line:30] INFO json loaded at time 2020-01-27 15:16:02
2020-01-27 15:16:02,561 load_json.py[line:91] INFO data constructed
2020-01-27 15:16:02,561 load_json.py[line:102] INFO data updated at 1580109362.56191
2020-01-27 15:16:09,997 load_json.py[line:30] INFO json loaded at time 2020-01-27 15:16:09
2020-01-27 15:16:19,253 load_json.py[line:30] INFO json loaded at time 2020-01-27 15:16:19
2020-01-27 15:16:31,564 load_json.py[line:30] INFO json loaded at time 2020-01-27 15:16:31
2020-01-27 15:16:44,223 load_json.py[line:30] INFO json loaded at time 2020-01-27 15:16:44
2020-01-27 15:16:52,551 load_json.py[line:33] ERROR json load failed, waiting for around 15 seconds
2020-01-27 15:16:52,552 load_json.py[line:34] ERROR 'data'
Traceback (most recent call last):
  File "load_json.py", line 28, in load_response
    if not response['data']['listByArea']:
KeyError: 'data'
2020-01-27 15:17:11,511 load_json.py[line:30] INFO json loaded at time 2020-01-27 15:17:11
2020-01-27 15:17:21,455 load_json.py[line:33] ERROR json load failed, waiting for around 15 seconds
2020-01-27 15:17:21,455 load_json.py[line:34] ERROR 'data'
Traceback (most recent call last):
  File "load_json.py", line 28, in load_response
    if not response['data']['listByArea']:
KeyError: 'data'
2020-01-27 15:17:41,906 load_json.py[line:30] INFO json loaded at time 2020-01-27 15:17:41
2020-01-27 15:17:53,596 load_json.py[line:30] INFO json loaded at time 2020-01-27 15:17:53
2020-01-27 15:18:05,392 load_json.py[line:30] INFO json loaded at time 2020-01-27 15:18:05
2020-01-27 15:18:15,878 load_json.py[line:33] ERROR json load failed, waiting for around 15 seconds
2020-01-27 15:18:15,878 load_json.py[line:34] ERROR 'data'
Traceback (most recent call last):
  File "load_json.py", line 28, in load_response
    if not response['data']['listByArea']:
KeyError: 'data'
2020-01-27 15:18:34,222 load_json.py[line:30] INFO json loaded at time 2020-01-27 15:18:34
2020-01-27 15:18:43,525 load_json.py[line:30] INFO json loaded at time 2020-01-27 15:18:43
2020-01-27 15:18:56,163 load_json.py[line:33] ERROR json load failed, waiting for around 15 seconds
2020-01-27 15:18:56,164 load_json.py[line:34] ERROR 'data'
Traceback (most recent call last):
  File "load_json.py", line 28, in load_response
    if not response['data']['listByArea']:
KeyError: 'data'
2020-01-27 15:19:14,175 load_json.py[line:33] ERROR json load failed, waiting for around 15 seconds
2020-01-27 15:19:14,175 load_json.py[line:34] ERROR 'data'
Traceback (most recent call last):
  File "load_json.py", line 28, in load_response
    if not response['data']['listByArea']:
KeyError: 'data'

During handling of the above exception, another exception occurred:

Traceback (most recent call last):
  File "load_json.py", line 28, in load_response
    if not response['data']['listByArea']:
KeyError: 'data'
2020-01-27 15:19:30,628 load_json.py[line:30] INFO json loaded at time 2020-01-27 15:19:30
2020-01-27 15:19:32,710 load_json.py[line:30] INFO json loaded at time 2020-01-27 15:19:32
2020-01-27 15:19:32,711 load_json.py[line:91] INFO data constructed
2020-01-27 15:19:32,711 load_json.py[line:102] INFO data updated at 1580109572.7119298
2020-01-27 15:19:38,815 load_json.py[line:30] INFO json loaded at time 2020-01-27 15:19:38
2020-01-27 15:19:52,830 load_json.py[line:33] ERROR json load failed, waiting for around 15 seconds
2020-01-27 15:19:52,831 load_json.py[line:34] ERROR 'data'
Traceback (most recent call last):
  File "load_json.py", line 28, in load_response
    if not response['data']['listByArea']:
KeyError: 'data'
2020-01-27 15:20:10,946 load_json.py[line:30] INFO json loaded at time 2020-01-27 15:20:10
2020-01-27 15:20:11,693 load_json.py[line:30] INFO json loaded at time 2020-01-27 15:20:11
2020-01-27 15:20:11,694 load_json.py[line:91] INFO data constructed
2020-01-27 15:20:11,694 load_json.py[line:102] INFO data updated at 1580109611.6941595
2020-01-27 15:20:20,965 load_json.py[line:33] ERROR json load failed, waiting for around 15 seconds
2020-01-27 15:20:20,965 load_json.py[line:34] ERROR 'data'
Traceback (most recent call last):
  File "load_json.py", line 28, in load_response
    if not response['data']['listByArea']:
KeyError: 'data'
2020-01-27 15:20:40,521 load_json.py[line:30] INFO json loaded at time 2020-01-27 15:20:40
2020-01-27 15:20:40,803 load_json.py[line:33] ERROR json load failed, waiting for around 15 seconds
2020-01-27 15:20:40,803 load_json.py[line:34] ERROR 'data'
Traceback (most recent call last):
  File "load_json.py", line 28, in load_response
    if not response['data']['listByArea']:
KeyError: 'data'
2020-01-27 15:20:56,436 load_json.py[line:33] ERROR json load failed, waiting for around 15 seconds
2020-01-27 15:20:56,436 load_json.py[line:34] ERROR 'data'
Traceback (most recent call last):
  File "load_json.py", line 28, in load_response
    if not response['data']['listByArea']:
KeyError: 'data'

During handling of the above exception, another exception occurred:

Traceback (most recent call last):
  File "load_json.py", line 28, in load_response
    if not response['data']['listByArea']:
KeyError: 'data'
2020-01-27 15:21:15,439 load_json.py[line:30] INFO json loaded at time 2020-01-27 15:21:15
2020-01-27 15:21:28,458 load_json.py[line:30] INFO json loaded at time 2020-01-27 15:21:28
2020-01-27 15:21:38,317 load_json.py[line:33] ERROR json load failed, waiting for around 15 seconds
2020-01-27 15:21:38,317 load_json.py[line:34] ERROR 'data'
Traceback (most recent call last):
  File "load_json.py", line 28, in load_response
    if not response['data']['listByArea']:
KeyError: 'data'
2020-01-27 15:21:57,084 load_json.py[line:33] ERROR json load failed, waiting for around 15 seconds
2020-01-27 15:21:57,084 load_json.py[line:34] ERROR 'data'
Traceback (most recent call last):
  File "load_json.py", line 28, in load_response
    if not response['data']['listByArea']:
KeyError: 'data'

During handling of the above exception, another exception occurred:

Traceback (most recent call last):
  File "load_json.py", line 28, in load_response
    if not response['data']['listByArea']:
KeyError: 'data'
2020-01-27 15:22:15,092 load_json.py[line:33] ERROR json load failed, waiting for around 15 seconds
2020-01-27 15:22:15,092 load_json.py[line:34] ERROR 'data'
Traceback (most recent call last):
  File "load_json.py", line 28, in load_response
    if not response['data']['listByArea']:
KeyError: 'data'

During handling of the above exception, another exception occurred:

Traceback (most recent call last):
  File "load_json.py", line 28, in load_response
    if not response['data']['listByArea']:
KeyError: 'data'

During handling of the above exception, another exception occurred:

Traceback (most recent call last):
  File "load_json.py", line 28, in load_response
    if not response['data']['listByArea']:
KeyError: 'data'
2020-01-27 15:22:32,187 load_json.py[line:33] ERROR json load failed, waiting for around 15 seconds
2020-01-27 15:22:32,188 load_json.py[line:34] ERROR 'data'
Traceback (most recent call last):
  File "load_json.py", line 28, in load_response
    if not response['data']['listByArea']:
KeyError: 'data'

During handling of the above exception, another exception occurred:

Traceback (most recent call last):
  File "load_json.py", line 28, in load_response
    if not response['data']['listByArea']:
KeyError: 'data'

During handling of the above exception, another exception occurred:

Traceback (most recent call last):
  File "load_json.py", line 28, in load_response
    if not response['data']['listByArea']:
KeyError: 'data'

During handling of the above exception, another exception occurred:

Traceback (most recent call last):
  File "load_json.py", line 28, in load_response
    if not response['data']['listByArea']:
KeyError: 'data'
2020-01-27 15:22:49,263 load_json.py[line:30] INFO json loaded at time 2020-01-27 15:22:49
2020-01-27 15:22:58,667 load_json.py[line:30] INFO json loaded at time 2020-01-27 15:22:58
2020-01-27 15:23:14,008 load_json.py[line:33] ERROR json load failed, waiting for around 15 seconds
2020-01-27 15:23:14,008 load_json.py[line:34] ERROR 'data'
Traceback (most recent call last):
  File "load_json.py", line 28, in load_response
    if not response['data']['listByArea']:
KeyError: 'data'
2020-01-27 15:23:31,748 load_json.py[line:33] ERROR json load failed, waiting for around 15 seconds
2020-01-27 15:23:31,749 load_json.py[line:34] ERROR 'data'
Traceback (most recent call last):
  File "load_json.py", line 28, in load_response
    if not response['data']['listByArea']:
KeyError: 'data'

During handling of the above exception, another exception occurred:

Traceback (most recent call last):
  File "load_json.py", line 28, in load_response
    if not response['data']['listByArea']:
KeyError: 'data'
2020-01-27 15:23:50,324 load_json.py[line:33] ERROR json load failed, waiting for around 15 seconds
2020-01-27 15:23:50,324 load_json.py[line:34] ERROR 'data'
Traceback (most recent call last):
  File "load_json.py", line 28, in load_response
    if not response['data']['listByArea']:
KeyError: 'data'

During handling of the above exception, another exception occurred:

Traceback (most recent call last):
  File "load_json.py", line 28, in load_response
    if not response['data']['listByArea']:
KeyError: 'data'

During handling of the above exception, another exception occurred:

Traceback (most recent call last):
  File "load_json.py", line 28, in load_response
    if not response['data']['listByArea']:
KeyError: 'data'
2020-01-27 15:24:06,721 load_json.py[line:33] ERROR json load failed, waiting for around 15 seconds
2020-01-27 15:24:06,721 load_json.py[line:34] ERROR 'data'
Traceback (most recent call last):
  File "load_json.py", line 28, in load_response
    if not response['data']['listByArea']:
KeyError: 'data'

During handling of the above exception, another exception occurred:

Traceback (most recent call last):
  File "load_json.py", line 28, in load_response
    if not response['data']['listByArea']:
KeyError: 'data'

During handling of the above exception, another exception occurred:

Traceback (most recent call last):
  File "load_json.py", line 28, in load_response
    if not response['data']['listByArea']:
KeyError: 'data'

During handling of the above exception, another exception occurred:

Traceback (most recent call last):
  File "load_json.py", line 28, in load_response
    if not response['data']['listByArea']:
KeyError: 'data'
2020-01-27 15:24:24,507 load_json.py[line:30] INFO json loaded at time 2020-01-27 15:24:24
2020-01-27 15:24:37,845 load_json.py[line:33] ERROR json load failed, waiting for around 15 seconds
2020-01-27 15:24:37,846 load_json.py[line:34] ERROR 'data'
Traceback (most recent call last):
  File "load_json.py", line 28, in load_response
    if not response['data']['listByArea']:
KeyError: 'data'
2020-01-27 15:24:58,068 load_json.py[line:33] ERROR json load failed, waiting for around 15 seconds
2020-01-27 15:24:58,068 load_json.py[line:34] ERROR 'data'
Traceback (most recent call last):
  File "load_json.py", line 28, in load_response
    if not response['data']['listByArea']:
KeyError: 'data'

During handling of the above exception, another exception occurred:

Traceback (most recent call last):
  File "load_json.py", line 28, in load_response
    if not response['data']['listByArea']:
KeyError: 'data'
2020-01-27 15:25:18,506 load_json.py[line:30] INFO json loaded at time 2020-01-27 15:25:18
2020-01-27 15:25:29,000 load_json.py[line:30] INFO json loaded at time 2020-01-27 15:25:29
2020-01-27 15:25:44,583 load_json.py[line:30] INFO json loaded at time 2020-01-27 15:25:44
2020-01-27 15:25:59,899 load_json.py[line:30] INFO json loaded at time 2020-01-27 15:25:59
2020-01-27 15:26:07,683 load_json.py[line:30] INFO json loaded at time 2020-01-27 15:26:07
2020-01-27 15:26:17,090 load_json.py[line:30] INFO json loaded at time 2020-01-27 15:26:17
2020-01-27 15:26:24,048 load_json.py[line:33] ERROR json load failed, waiting for around 15 seconds
2020-01-27 15:26:24,048 load_json.py[line:34] ERROR 'data'
Traceback (most recent call last):
  File "load_json.py", line 28, in load_response
    if not response['data']['listByArea']:
KeyError: 'data'
2020-01-27 15:26:41,744 load_json.py[line:33] ERROR json load failed, waiting for around 15 seconds
2020-01-27 15:26:41,744 load_json.py[line:34] ERROR 'data'
Traceback (most recent call last):
  File "load_json.py", line 28, in load_response
    if not response['data']['listByArea']:
KeyError: 'data'

During handling of the above exception, another exception occurred:

Traceback (most recent call last):
  File "load_json.py", line 28, in load_response
    if not response['data']['listByArea']:
KeyError: 'data'
2020-01-27 15:26:58,873 load_json.py[line:33] ERROR json load failed, waiting for around 15 seconds
2020-01-27 15:26:58,873 load_json.py[line:34] ERROR 'data'
Traceback (most recent call last):
  File "load_json.py", line 28, in load_response
    if not response['data']['listByArea']:
KeyError: 'data'

During handling of the above exception, another exception occurred:

Traceback (most recent call last):
  File "load_json.py", line 28, in load_response
    if not response['data']['listByArea']:
KeyError: 'data'

During handling of the above exception, another exception occurred:

Traceback (most recent call last):
  File "load_json.py", line 28, in load_response
    if not response['data']['listByArea']:
KeyError: 'data'
2020-01-27 15:27:18,988 load_json.py[line:30] INFO json loaded at time 2020-01-27 15:27:18
2020-01-27 15:27:29,244 load_json.py[line:33] ERROR json load failed, waiting for around 15 seconds
2020-01-27 15:27:29,245 load_json.py[line:34] ERROR 'data'
Traceback (most recent call last):
  File "load_json.py", line 28, in load_response
    if not response['data']['listByArea']:
KeyError: 'data'
2020-01-27 15:27:49,781 load_json.py[line:30] INFO json loaded at time 2020-01-27 15:27:49
2020-01-27 15:27:57,914 load_json.py[line:33] ERROR json load failed, waiting for around 15 seconds
2020-01-27 15:27:57,915 load_json.py[line:34] ERROR 'data'
Traceback (most recent call last):
  File "load_json.py", line 28, in load_response
    if not response['data']['listByArea']:
KeyError: 'data'
2020-01-27 15:28:17,932 load_json.py[line:30] INFO json loaded at time 2020-01-27 15:28:17
2020-01-27 15:28:18,800 load_json.py[line:30] INFO json loaded at time 2020-01-27 15:28:18
2020-01-27 15:28:29,500 load_json.py[line:33] ERROR json load failed, waiting for around 15 seconds
2020-01-27 15:28:29,500 load_json.py[line:34] ERROR 'data'
Traceback (most recent call last):
  File "load_json.py", line 28, in load_response
    if not response['data']['listByArea']:
KeyError: 'data'
2020-01-27 15:28:46,238 load_json.py[line:30] INFO json loaded at time 2020-01-27 15:28:46
2020-01-27 15:28:46,970 load_json.py[line:30] INFO json loaded at time 2020-01-27 15:28:46
2020-01-27 15:28:46,971 load_json.py[line:91] INFO data constructed
2020-01-27 15:28:46,971 load_json.py[line:102] INFO data updated at 1580110126.9716318
2020-01-27 15:28:54,409 load_json.py[line:30] INFO json loaded at time 2020-01-27 15:28:54
2020-01-27 15:28:54,691 load_json.py[line:33] ERROR json load failed, waiting for around 15 seconds
2020-01-27 15:28:54,692 load_json.py[line:34] ERROR 'data'
Traceback (most recent call last):
  File "load_json.py", line 28, in load_response
    if not response['data']['listByArea']:
KeyError: 'data'
2020-01-27 15:29:11,739 load_json.py[line:30] INFO json loaded at time 2020-01-27 15:29:11
2020-01-27 15:29:19,001 load_json.py[line:30] INFO json loaded at time 2020-01-27 15:29:19
2020-01-27 15:29:30,531 load_json.py[line:30] INFO json loaded at time 2020-01-27 15:29:30
2020-01-27 15:29:40,731 load_json.py[line:30] INFO json loaded at time 2020-01-27 15:29:40
2020-01-27 15:29:55,530 load_json.py[line:33] ERROR json load failed, waiting for around 15 seconds
2020-01-27 15:29:55,530 load_json.py[line:34] ERROR 'data'
Traceback (most recent call last):
  File "load_json.py", line 28, in load_response
    if not response['data']['listByArea']:
KeyError: 'data'
2020-01-27 15:30:16,530 load_json.py[line:30] INFO json loaded at time 2020-01-27 15:30:16
2020-01-27 15:30:27,850 load_json.py[line:33] ERROR json load failed, waiting for around 15 seconds
2020-01-27 15:30:27,850 load_json.py[line:34] ERROR 'data'
Traceback (most recent call last):
  File "load_json.py", line 28, in load_response
    if not response['data']['listByArea']:
KeyError: 'data'
2020-01-27 15:30:47,951 load_json.py[line:30] INFO json loaded at time 2020-01-27 15:30:47
2020-01-27 15:31:03,102 load_json.py[line:33] ERROR json load failed, waiting for around 15 seconds
2020-01-27 15:31:03,102 load_json.py[line:34] ERROR 'data'
Traceback (most recent call last):
  File "load_json.py", line 28, in load_response
    if not response['data']['listByArea']:
KeyError: 'data'
2020-01-27 15:31:20,072 load_json.py[line:30] INFO json loaded at time 2020-01-27 15:31:20
2020-01-27 15:31:30,220 load_json.py[line:33] ERROR json load failed, waiting for around 15 seconds
2020-01-27 15:31:30,220 load_json.py[line:34] ERROR 'data'
Traceback (most recent call last):
  File "load_json.py", line 28, in load_response
    if not response['data']['listByArea']:
KeyError: 'data'
2020-01-27 15:31:46,317 load_json.py[line:30] INFO json loaded at time 2020-01-27 15:31:46
2020-01-27 15:31:52,861 load_json.py[line:30] INFO json loaded at time 2020-01-27 15:31:52
2020-01-27 15:32:03,534 load_json.py[line:30] INFO json loaded at time 2020-01-27 15:32:03
2020-01-27 15:32:13,855 load_json.py[line:33] ERROR json load failed, waiting for around 15 seconds
2020-01-27 15:32:13,855 load_json.py[line:34] ERROR 'data'
Traceback (most recent call last):
  File "load_json.py", line 28, in load_response
    if not response['data']['listByArea']:
KeyError: 'data'
2020-01-27 15:32:33,011 load_json.py[line:30] INFO json loaded at time 2020-01-27 15:32:33
2020-01-27 15:32:46,196 load_json.py[line:33] ERROR json load failed, waiting for around 15 seconds
2020-01-27 15:32:46,196 load_json.py[line:34] ERROR 'data'
Traceback (most recent call last):
  File "load_json.py", line 28, in load_response
    if not response['data']['listByArea']:
KeyError: 'data'
2020-01-27 15:33:03,685 load_json.py[line:33] ERROR json load failed, waiting for around 15 seconds
2020-01-27 15:33:03,686 load_json.py[line:34] ERROR 'data'
Traceback (most recent call last):
  File "load_json.py", line 28, in load_response
    if not response['data']['listByArea']:
KeyError: 'data'

During handling of the above exception, another exception occurred:

Traceback (most recent call last):
  File "load_json.py", line 28, in load_response
    if not response['data']['listByArea']:
KeyError: 'data'
2020-01-27 15:33:21,960 load_json.py[line:33] ERROR json load failed, waiting for around 15 seconds
2020-01-27 15:33:21,961 load_json.py[line:34] ERROR 'data'
Traceback (most recent call last):
  File "load_json.py", line 28, in load_response
    if not response['data']['listByArea']:
KeyError: 'data'

During handling of the above exception, another exception occurred:

Traceback (most recent call last):
  File "load_json.py", line 28, in load_response
    if not response['data']['listByArea']:
KeyError: 'data'

During handling of the above exception, another exception occurred:

Traceback (most recent call last):
  File "load_json.py", line 28, in load_response
    if not response['data']['listByArea']:
KeyError: 'data'
2020-01-27 15:33:38,320 load_json.py[line:30] INFO json loaded at time 2020-01-27 15:33:38
2020-01-27 15:33:46,986 load_json.py[line:30] INFO json loaded at time 2020-01-27 15:33:46
2020-01-27 15:33:57,374 load_json.py[line:30] INFO json loaded at time 2020-01-27 15:33:57
2020-01-27 15:34:09,514 load_json.py[line:30] INFO json loaded at time 2020-01-27 15:34:09
2020-01-27 15:34:18,148 load_json.py[line:33] ERROR json load failed, waiting for around 15 seconds
2020-01-27 15:34:18,149 load_json.py[line:34] ERROR 'data'
Traceback (most recent call last):
  File "load_json.py", line 28, in load_response
    if not response['data']['listByArea']:
KeyError: 'data'
2020-01-27 15:34:37,953 load_json.py[line:33] ERROR json load failed, waiting for around 15 seconds
2020-01-27 15:34:37,954 load_json.py[line:34] ERROR 'data'
Traceback (most recent call last):
  File "load_json.py", line 28, in load_response
    if not response['data']['listByArea']:
KeyError: 'data'

During handling of the above exception, another exception occurred:

Traceback (most recent call last):
  File "load_json.py", line 28, in load_response
    if not response['data']['listByArea']:
KeyError: 'data'
2020-01-27 15:34:58,458 load_json.py[line:30] INFO json loaded at time 2020-01-27 15:34:58
2020-01-27 15:35:06,375 load_json.py[line:33] ERROR json load failed, waiting for around 15 seconds
2020-01-27 15:35:06,375 load_json.py[line:34] ERROR 'data'
Traceback (most recent call last):
  File "load_json.py", line 28, in load_response
    if not response['data']['listByArea']:
KeyError: 'data'
2020-01-27 15:35:23,998 load_json.py[line:30] INFO json loaded at time 2020-01-27 15:35:23
2020-01-27 15:35:32,958 load_json.py[line:30] INFO json loaded at time 2020-01-27 15:35:32
2020-01-27 15:35:41,690 load_json.py[line:30] INFO json loaded at time 2020-01-27 15:35:41
2020-01-27 15:35:55,199 load_json.py[line:30] INFO json loaded at time 2020-01-27 15:35:55
2020-01-27 15:36:02,829 load_json.py[line:33] ERROR json load failed, waiting for around 15 seconds
2020-01-27 15:36:02,830 load_json.py[line:34] ERROR 'data'
Traceback (most recent call last):
  File "load_json.py", line 28, in load_response
    if not response['data']['listByArea']:
KeyError: 'data'
2020-01-27 15:36:21,487 load_json.py[line:30] INFO json loaded at time 2020-01-27 15:36:21
2020-01-27 15:36:31,377 load_json.py[line:30] INFO json loaded at time 2020-01-27 15:36:31
2020-01-27 15:36:40,934 load_json.py[line:30] INFO json loaded at time 2020-01-27 15:36:40
2020-01-27 15:36:54,216 load_json.py[line:30] INFO json loaded at time 2020-01-27 15:36:54
2020-01-27 15:37:05,726 load_json.py[line:30] INFO json loaded at time 2020-01-27 15:37:05
2020-01-27 15:37:20,662 load_json.py[line:30] INFO json loaded at time 2020-01-27 15:37:20
2020-01-27 15:37:30,842 load_json.py[line:30] INFO json loaded at time 2020-01-27 15:37:30
2020-01-27 15:37:41,633 load_json.py[line:30] INFO json loaded at time 2020-01-27 15:37:41
2020-01-27 15:37:47,746 load_json.py[line:33] ERROR json load failed, waiting for around 15 seconds
2020-01-27 15:37:47,747 load_json.py[line:34] ERROR 'data'
Traceback (most recent call last):
  File "load_json.py", line 28, in load_response
    if not response['data']['listByArea']:
KeyError: 'data'
2020-01-27 15:38:05,152 load_json.py[line:30] INFO json loaded at time 2020-01-27 15:38:05
2020-01-27 15:38:14,582 load_json.py[line:30] INFO json loaded at time 2020-01-27 15:38:14
2020-01-27 15:38:24,069 load_json.py[line:30] INFO json loaded at time 2020-01-27 15:38:24
2020-01-27 15:38:36,197 load_json.py[line:33] ERROR json load failed, waiting for around 15 seconds
2020-01-27 15:38:36,198 load_json.py[line:34] ERROR 'data'
Traceback (most recent call last):
  File "load_json.py", line 28, in load_response
    if not response['data']['listByArea']:
KeyError: 'data'
2020-01-27 15:38:53,036 load_json.py[line:30] INFO json loaded at time 2020-01-27 15:38:53
2020-01-27 15:39:00,839 load_json.py[line:30] INFO json loaded at time 2020-01-27 15:39:00
2020-01-27 15:39:16,021 load_json.py[line:30] INFO json loaded at time 2020-01-27 15:39:16
2020-01-27 15:39:26,577 load_json.py[line:33] ERROR json load failed, waiting for around 15 seconds
2020-01-27 15:39:26,577 load_json.py[line:34] ERROR 'data'
Traceback (most recent call last):
  File "load_json.py", line 28, in load_response
    if not response['data']['listByArea']:
KeyError: 'data'
2020-01-27 15:39:45,610 load_json.py[line:33] ERROR json load failed, waiting for around 15 seconds
2020-01-27 15:39:45,611 load_json.py[line:34] ERROR 'data'
Traceback (most recent call last):
  File "load_json.py", line 28, in load_response
    if not response['data']['listByArea']:
KeyError: 'data'

During handling of the above exception, another exception occurred:

Traceback (most recent call last):
  File "load_json.py", line 28, in load_response
    if not response['data']['listByArea']:
KeyError: 'data'
2020-01-27 15:40:03,738 load_json.py[line:33] ERROR json load failed, waiting for around 15 seconds
2020-01-27 15:40:03,739 load_json.py[line:34] ERROR 'data'
Traceback (most recent call last):
  File "load_json.py", line 28, in load_response
    if not response['data']['listByArea']:
KeyError: 'data'

During handling of the above exception, another exception occurred:

Traceback (most recent call last):
  File "load_json.py", line 28, in load_response
    if not response['data']['listByArea']:
KeyError: 'data'

During handling of the above exception, another exception occurred:

Traceback (most recent call last):
  File "load_json.py", line 28, in load_response
    if not response['data']['listByArea']:
KeyError: 'data'
2020-01-27 15:40:19,962 load_json.py[line:33] ERROR json load failed, waiting for around 15 seconds
2020-01-27 15:40:19,962 load_json.py[line:34] ERROR 'data'
Traceback (most recent call last):
  File "load_json.py", line 28, in load_response
    if not response['data']['listByArea']:
KeyError: 'data'

During handling of the above exception, another exception occurred:

Traceback (most recent call last):
  File "load_json.py", line 28, in load_response
    if not response['data']['listByArea']:
KeyError: 'data'

During handling of the above exception, another exception occurred:

Traceback (most recent call last):
  File "load_json.py", line 28, in load_response
    if not response['data']['listByArea']:
KeyError: 'data'

During handling of the above exception, another exception occurred:

Traceback (most recent call last):
  File "load_json.py", line 28, in load_response
    if not response['data']['listByArea']:
KeyError: 'data'
2020-01-27 15:40:40,296 load_json.py[line:30] INFO json loaded at time 2020-01-27 15:40:40
2020-01-27 15:40:47,400 load_json.py[line:30] INFO json loaded at time 2020-01-27 15:40:47
2020-01-27 15:40:58,733 load_json.py[line:30] INFO json loaded at time 2020-01-27 15:40:58
2020-01-27 15:41:10,202 load_json.py[line:30] INFO json loaded at time 2020-01-27 15:41:10
2020-01-27 15:41:24,169 load_json.py[line:30] INFO json loaded at time 2020-01-27 15:41:24
2020-01-27 15:41:39,266 load_json.py[line:30] INFO json loaded at time 2020-01-27 15:41:39
2020-01-27 15:41:53,694 load_json.py[line:30] INFO json loaded at time 2020-01-27 15:41:53
2020-01-27 15:42:07,160 load_json.py[line:30] INFO json loaded at time 2020-01-27 15:42:07
2020-01-27 15:42:14,777 load_json.py[line:30] INFO json loaded at time 2020-01-27 15:42:14
2020-01-27 15:42:20,381 load_json.py[line:33] ERROR json load failed, waiting for around 15 seconds
2020-01-27 15:42:20,382 load_json.py[line:34] ERROR 'data'
Traceback (most recent call last):
  File "load_json.py", line 28, in load_response
    if not response['data']['listByArea']:
KeyError: 'data'
2020-01-27 15:42:39,604 load_json.py[line:30] INFO json loaded at time 2020-01-27 15:42:39
2020-01-27 15:42:51,467 load_json.py[line:30] INFO json loaded at time 2020-01-27 15:42:51
2020-01-27 15:43:05,703 load_json.py[line:33] ERROR json load failed, waiting for around 15 seconds
2020-01-27 15:43:05,703 load_json.py[line:34] ERROR 'data'
Traceback (most recent call last):
  File "load_json.py", line 28, in load_response
    if not response['data']['listByArea']:
KeyError: 'data'
2020-01-27 15:43:21,708 load_json.py[line:30] INFO json loaded at time 2020-01-27 15:43:21
2020-01-27 15:43:32,046 load_json.py[line:30] INFO json loaded at time 2020-01-27 15:43:32
2020-01-27 15:43:38,868 load_json.py[line:30] INFO json loaded at time 2020-01-27 15:43:38
2020-01-27 15:43:49,678 load_json.py[line:30] INFO json loaded at time 2020-01-27 15:43:49
2020-01-27 15:44:00,506 load_json.py[line:33] ERROR json load failed, waiting for around 15 seconds
2020-01-27 15:44:00,507 load_json.py[line:34] ERROR 'data'
Traceback (most recent call last):
  File "load_json.py", line 28, in load_response
    if not response['data']['listByArea']:
KeyError: 'data'
2020-01-27 15:44:20,458 load_json.py[line:33] ERROR json load failed, waiting for around 15 seconds
2020-01-27 15:44:20,459 load_json.py[line:34] ERROR 'data'
Traceback (most recent call last):
  File "load_json.py", line 28, in load_response
    if not response['data']['listByArea']:
KeyError: 'data'

During handling of the above exception, another exception occurred:

Traceback (most recent call last):
  File "load_json.py", line 28, in load_response
    if not response['data']['listByArea']:
KeyError: 'data'
2020-01-27 15:44:40,593 load_json.py[line:30] INFO json loaded at time 2020-01-27 15:44:40
2020-01-27 15:44:56,204 load_json.py[line:30] INFO json loaded at time 2020-01-27 15:44:56
2020-01-27 15:45:07,071 load_json.py[line:30] INFO json loaded at time 2020-01-27 15:45:07
2020-01-27 15:45:15,652 load_json.py[line:30] INFO json loaded at time 2020-01-27 15:45:15
2020-01-27 15:45:23,791 load_json.py[line:33] ERROR json load failed, waiting for around 15 seconds
2020-01-27 15:45:23,791 load_json.py[line:34] ERROR 'data'
Traceback (most recent call last):
  File "load_json.py", line 28, in load_response
    if not response['data']['listByArea']:
KeyError: 'data'
2020-01-27 15:45:41,821 load_json.py[line:30] INFO json loaded at time 2020-01-27 15:45:41
2020-01-27 15:45:56,447 load_json.py[line:33] ERROR json load failed, waiting for around 15 seconds
2020-01-27 15:45:56,448 load_json.py[line:34] ERROR 'data'
Traceback (most recent call last):
  File "load_json.py", line 28, in load_response
    if not response['data']['listByArea']:
KeyError: 'data'
2020-01-27 15:46:13,976 load_json.py[line:30] INFO json loaded at time 2020-01-27 15:46:13
2020-01-27 15:46:24,988 load_json.py[line:30] INFO json loaded at time 2020-01-27 15:46:24
2020-01-27 15:46:31,523 load_json.py[line:33] ERROR json load failed, waiting for around 15 seconds
2020-01-27 15:46:31,523 load_json.py[line:34] ERROR 'data'
Traceback (most recent call last):
  File "load_json.py", line 28, in load_response
    if not response['data']['listByArea']:
KeyError: 'data'
2020-01-27 15:46:49,625 load_json.py[line:33] ERROR json load failed, waiting for around 15 seconds
2020-01-27 15:46:49,625 load_json.py[line:34] ERROR 'data'
Traceback (most recent call last):
  File "load_json.py", line 28, in load_response
    if not response['data']['listByArea']:
KeyError: 'data'

During handling of the above exception, another exception occurred:

Traceback (most recent call last):
  File "load_json.py", line 28, in load_response
    if not response['data']['listByArea']:
KeyError: 'data'
2020-01-27 15:47:09,928 load_json.py[line:30] INFO json loaded at time 2020-01-27 15:47:09
2020-01-27 15:47:18,027 load_json.py[line:30] INFO json loaded at time 2020-01-27 15:47:18
2020-01-27 15:47:24,714 load_json.py[line:30] INFO json loaded at time 2020-01-27 15:47:24
2020-01-27 15:47:35,820 load_json.py[line:30] INFO json loaded at time 2020-01-27 15:47:35
2020-01-27 15:47:44,842 load_json.py[line:33] ERROR json load failed, waiting for around 15 seconds
2020-01-27 15:47:44,843 load_json.py[line:34] ERROR 'data'
Traceback (most recent call last):
  File "load_json.py", line 28, in load_response
    if not response['data']['listByArea']:
KeyError: 'data'
2020-01-27 15:48:02,801 load_json.py[line:30] INFO json loaded at time 2020-01-27 15:48:02
2020-01-27 15:48:15,272 load_json.py[line:30] INFO json loaded at time 2020-01-27 15:48:15
2020-01-27 15:48:29,702 load_json.py[line:30] INFO json loaded at time 2020-01-27 15:48:29
2020-01-27 15:48:39,775 load_json.py[line:33] ERROR json load failed, waiting for around 15 seconds
2020-01-27 15:48:39,776 load_json.py[line:34] ERROR 'data'
Traceback (most recent call last):
  File "load_json.py", line 28, in load_response
    if not response['data']['listByArea']:
KeyError: 'data'
2020-01-27 15:48:56,552 load_json.py[line:30] INFO json loaded at time 2020-01-27 15:48:56
2020-01-27 15:49:08,888 load_json.py[line:30] INFO json loaded at time 2020-01-27 15:49:08
2020-01-27 15:49:19,250 load_json.py[line:30] INFO json loaded at time 2020-01-27 15:49:19
2020-01-27 15:49:29,963 load_json.py[line:33] ERROR json load failed, waiting for around 15 seconds
2020-01-27 15:49:29,963 load_json.py[line:34] ERROR 'data'
Traceback (most recent call last):
  File "load_json.py", line 28, in load_response
    if not response['data']['listByArea']:
KeyError: 'data'
2020-01-27 15:49:48,651 load_json.py[line:30] INFO json loaded at time 2020-01-27 15:49:48
2020-01-27 15:50:00,804 load_json.py[line:30] INFO json loaded at time 2020-01-27 15:50:00
2020-01-27 15:50:07,315 load_json.py[line:30] INFO json loaded at time 2020-01-27 15:50:07
2020-01-27 15:50:14,812 load_json.py[line:30] INFO json loaded at time 2020-01-27 15:50:14
2020-01-27 15:50:29,936 load_json.py[line:33] ERROR json load failed, waiting for around 15 seconds
2020-01-27 15:50:29,936 load_json.py[line:34] ERROR 'data'
Traceback (most recent call last):
  File "load_json.py", line 28, in load_response
    if not response['data']['listByArea']:
KeyError: 'data'
2020-01-27 15:50:48,910 load_json.py[line:30] INFO json loaded at time 2020-01-27 15:50:48
2020-01-27 15:51:00,677 load_json.py[line:33] ERROR json load failed, waiting for around 15 seconds
2020-01-27 15:51:00,677 load_json.py[line:34] ERROR 'data'
Traceback (most recent call last):
  File "load_json.py", line 28, in load_response
    if not response['data']['listByArea']:
KeyError: 'data'
2020-01-27 15:51:20,403 load_json.py[line:30] INFO json loaded at time 2020-01-27 15:51:20
2020-01-27 15:51:30,008 load_json.py[line:30] INFO json loaded at time 2020-01-27 15:51:30
2020-01-27 15:51:43,120 load_json.py[line:30] INFO json loaded at time 2020-01-27 15:51:43
2020-01-27 15:51:57,604 load_json.py[line:30] INFO json loaded at time 2020-01-27 15:51:57
2020-01-27 15:52:08,795 load_json.py[line:30] INFO json loaded at time 2020-01-27 15:52:08
2020-01-27 15:52:19,134 load_json.py[line:30] INFO json loaded at time 2020-01-27 15:52:19
2020-01-27 15:52:34,315 load_json.py[line:30] INFO json loaded at time 2020-01-27 15:52:34
2020-01-27 15:52:45,771 load_json.py[line:30] INFO json loaded at time 2020-01-27 15:52:45
2020-01-27 15:52:58,914 load_json.py[line:33] ERROR json load failed, waiting for around 15 seconds
2020-01-27 15:52:58,915 load_json.py[line:34] ERROR 'data'
Traceback (most recent call last):
  File "load_json.py", line 28, in load_response
    if not response['data']['listByArea']:
KeyError: 'data'
2020-01-27 15:53:19,749 load_json.py[line:30] INFO json loaded at time 2020-01-27 15:53:19
2020-01-27 15:53:28,930 load_json.py[line:30] INFO json loaded at time 2020-01-27 15:53:28
2020-01-27 15:53:35,293 load_json.py[line:30] INFO json loaded at time 2020-01-27 15:53:35
2020-01-27 15:53:52,561 load_json.py[line:30] INFO json loaded at time 2020-01-27 15:53:52
2020-01-27 15:54:02,190 load_json.py[line:30] INFO json loaded at time 2020-01-27 15:54:02
2020-01-27 15:54:12,675 load_json.py[line:33] ERROR json load failed, waiting for around 15 seconds
2020-01-27 15:54:12,675 load_json.py[line:34] ERROR 'data'
Traceback (most recent call last):
  File "load_json.py", line 28, in load_response
    if not response['data']['listByArea']:
KeyError: 'data'
2020-01-27 15:54:29,477 load_json.py[line:30] INFO json loaded at time 2020-01-27 15:54:29
2020-01-27 15:54:44,673 load_json.py[line:30] INFO json loaded at time 2020-01-27 15:54:44
2020-01-27 15:54:59,293 load_json.py[line:30] INFO json loaded at time 2020-01-27 15:54:59
2020-01-27 15:55:13,563 load_json.py[line:30] INFO json loaded at time 2020-01-27 15:55:13
2020-01-27 15:55:21,914 load_json.py[line:33] ERROR json load failed, waiting for around 15 seconds
2020-01-27 15:55:21,915 load_json.py[line:34] ERROR 'data'
Traceback (most recent call last):
  File "load_json.py", line 28, in load_response
    if not response['data']['listByArea']:
KeyError: 'data'
2020-01-27 15:55:39,840 load_json.py[line:30] INFO json loaded at time 2020-01-27 15:55:39
2020-01-27 15:55:54,474 load_json.py[line:30] INFO json loaded at time 2020-01-27 15:55:54
2020-01-27 15:56:08,950 load_json.py[line:30] INFO json loaded at time 2020-01-27 15:56:08
2020-01-27 15:56:10,937 load_json.py[line:30] INFO json loaded at time 2020-01-27 15:56:10
2020-01-27 15:56:10,938 load_json.py[line:91] INFO data constructed
2020-01-27 15:56:10,939 load_json.py[line:102] INFO data updated at 1580111770.9386613
2020-01-27 15:56:22,272 load_json.py[line:30] INFO json loaded at time 2020-01-27 15:56:22
2020-01-27 15:56:23,004 load_json.py[line:30] INFO json loaded at time 2020-01-27 15:56:23
2020-01-27 15:56:23,005 load_json.py[line:91] INFO data constructed
2020-01-27 15:56:23,005 load_json.py[line:102] INFO data updated at 1580111783.0053513
2020-01-27 15:56:36,422 load_json.py[line:30] INFO json loaded at time 2020-01-27 15:56:36
2020-01-27 15:56:51,732 load_json.py[line:30] INFO json loaded at time 2020-01-27 15:56:51
2020-01-27 15:56:52,700 load_json.py[line:30] INFO json loaded at time 2020-01-27 15:56:52
2020-01-27 15:56:52,701 load_json.py[line:91] INFO data constructed
2020-01-27 15:56:52,701 load_json.py[line:102] INFO data updated at 1580111812.70105
2020-01-27 15:57:05,476 load_json.py[line:30] INFO json loaded at time 2020-01-27 15:57:05
2020-01-27 15:57:18,120 load_json.py[line:30] INFO json loaded at time 2020-01-27 15:57:18
2020-01-27 15:57:31,064 load_json.py[line:30] INFO json loaded at time 2020-01-27 15:57:31
2020-01-27 15:57:31,814 load_json.py[line:30] INFO json loaded at time 2020-01-27 15:57:31
2020-01-27 15:57:47,150 load_json.py[line:30] INFO json loaded at time 2020-01-27 15:57:47
2020-01-27 15:57:57,141 load_json.py[line:33] ERROR json load failed, waiting for around 15 seconds
2020-01-27 15:57:57,142 load_json.py[line:34] ERROR 'data'
Traceback (most recent call last):
  File "load_json.py", line 28, in load_response
    if not response['data']['listByArea']:
KeyError: 'data'
2020-01-27 15:58:15,007 load_json.py[line:30] INFO json loaded at time 2020-01-27 15:58:15
2020-01-27 15:58:23,264 load_json.py[line:33] ERROR json load failed, waiting for around 15 seconds
2020-01-27 15:58:23,264 load_json.py[line:34] ERROR 'data'
Traceback (most recent call last):
  File "load_json.py", line 28, in load_response
    if not response['data']['listByArea']:
KeyError: 'data'
2020-01-27 15:58:40,829 load_json.py[line:30] INFO json loaded at time 2020-01-27 15:58:40
2020-01-27 15:58:52,327 load_json.py[line:30] INFO json loaded at time 2020-01-27 15:58:52
2020-01-27 15:59:03,399 load_json.py[line:33] ERROR json load failed, waiting for around 15 seconds
2020-01-27 15:59:03,399 load_json.py[line:34] ERROR 'data'
Traceback (most recent call last):
  File "load_json.py", line 28, in load_response
    if not response['data']['listByArea']:
KeyError: 'data'
2020-01-27 15:59:23,478 load_json.py[line:30] INFO json loaded at time 2020-01-27 15:59:23
2020-01-27 15:59:29,350 load_json.py[line:30] INFO json loaded at time 2020-01-27 15:59:29
2020-01-27 15:59:39,300 load_json.py[line:30] INFO json loaded at time 2020-01-27 15:59:39
2020-01-27 15:59:54,318 load_json.py[line:30] INFO json loaded at time 2020-01-27 15:59:54
2020-01-27 16:00:07,414 load_json.py[line:33] ERROR json load failed, waiting for around 15 seconds
2020-01-27 16:00:07,414 load_json.py[line:34] ERROR 'data'
Traceback (most recent call last):
  File "load_json.py", line 28, in load_response
    if not response['data']['listByArea']:
KeyError: 'data'
2020-01-27 16:00:24,882 load_json.py[line:30] INFO json loaded at time 2020-01-27 16:00:24
2020-01-27 16:00:31,422 load_json.py[line:30] INFO json loaded at time 2020-01-27 16:00:31
2020-01-27 16:00:42,113 load_json.py[line:30] INFO json loaded at time 2020-01-27 16:00:42
2020-01-27 16:00:49,427 load_json.py[line:33] ERROR json load failed, waiting for around 15 seconds
2020-01-27 16:00:49,427 load_json.py[line:34] ERROR 'data'
Traceback (most recent call last):
  File "load_json.py", line 28, in load_response
    if not response['data']['listByArea']:
KeyError: 'data'
2020-01-27 16:01:05,575 load_json.py[line:30] INFO json loaded at time 2020-01-27 16:01:05
2020-01-27 16:01:21,611 load_json.py[line:30] INFO json loaded at time 2020-01-27 16:01:21
2020-01-27 16:01:30,258 load_json.py[line:33] ERROR json load failed, waiting for around 15 seconds
2020-01-27 16:01:30,258 load_json.py[line:34] ERROR 'data'
Traceback (most recent call last):
  File "load_json.py", line 28, in load_response
    if not response['data']['listByArea']:
KeyError: 'data'
2020-01-27 16:01:48,866 load_json.py[line:30] INFO json loaded at time 2020-01-27 16:01:48
2020-01-27 16:02:04,351 load_json.py[line:30] INFO json loaded at time 2020-01-27 16:02:04
2020-01-27 16:02:17,310 load_json.py[line:30] INFO json loaded at time 2020-01-27 16:02:17
2020-01-27 16:02:31,445 load_json.py[line:30] INFO json loaded at time 2020-01-27 16:02:31
2020-01-27 16:02:41,857 load_json.py[line:30] INFO json loaded at time 2020-01-27 16:02:41
2020-01-27 16:02:57,544 load_json.py[line:30] INFO json loaded at time 2020-01-27 16:02:57
2020-01-27 16:03:04,648 load_json.py[line:30] INFO json loaded at time 2020-01-27 16:03:04
2020-01-27 16:03:12,378 load_json.py[line:33] ERROR json load failed, waiting for around 15 seconds
2020-01-27 16:03:12,378 load_json.py[line:34] ERROR 'data'
Traceback (most recent call last):
  File "load_json.py", line 28, in load_response
    if not response['data']['listByArea']:
KeyError: 'data'
2020-01-27 16:03:31,622 load_json.py[line:30] INFO json loaded at time 2020-01-27 16:03:31
2020-01-27 16:03:46,924 load_json.py[line:30] INFO json loaded at time 2020-01-27 16:03:46
2020-01-27 16:03:59,618 load_json.py[line:30] INFO json loaded at time 2020-01-27 16:03:59
2020-01-27 16:04:13,218 load_json.py[line:30] INFO json loaded at time 2020-01-27 16:04:13
2020-01-27 16:04:19,560 load_json.py[line:30] INFO json loaded at time 2020-01-27 16:04:19
2020-01-27 16:04:28,789 load_json.py[line:30] INFO json loaded at time 2020-01-27 16:04:28
2020-01-27 16:04:37,276 load_json.py[line:30] INFO json loaded at time 2020-01-27 16:04:37
2020-01-27 16:04:47,499 load_json.py[line:33] ERROR json load failed, waiting for around 15 seconds
2020-01-27 16:04:47,499 load_json.py[line:34] ERROR 'data'
Traceback (most recent call last):
  File "load_json.py", line 28, in load_response
    if not response['data']['listByArea']:
KeyError: 'data'
2020-01-27 16:05:07,677 load_json.py[line:33] ERROR json load failed, waiting for around 15 seconds
2020-01-27 16:05:07,677 load_json.py[line:34] ERROR 'data'
Traceback (most recent call last):
  File "load_json.py", line 28, in load_response
    if not response['data']['listByArea']:
KeyError: 'data'

During handling of the above exception, another exception occurred:

Traceback (most recent call last):
  File "load_json.py", line 28, in load_response
    if not response['data']['listByArea']:
KeyError: 'data'
2020-01-27 16:05:23,748 load_json.py[line:30] INFO json loaded at time 2020-01-27 16:05:23
2020-01-27 16:05:38,855 load_json.py[line:33] ERROR json load failed, waiting for around 15 seconds
2020-01-27 16:05:38,855 load_json.py[line:34] ERROR 'data'
Traceback (most recent call last):
  File "load_json.py", line 28, in load_response
    if not response['data']['listByArea']:
KeyError: 'data'
2020-01-27 16:05:57,875 load_json.py[line:33] ERROR json load failed, waiting for around 15 seconds
2020-01-27 16:05:57,876 load_json.py[line:34] ERROR 'data'
Traceback (most recent call last):
  File "load_json.py", line 28, in load_response
    if not response['data']['listByArea']:
KeyError: 'data'

During handling of the above exception, another exception occurred:

Traceback (most recent call last):
  File "load_json.py", line 28, in load_response
    if not response['data']['listByArea']:
KeyError: 'data'
2020-01-27 16:06:18,673 load_json.py[line:30] INFO json loaded at time 2020-01-27 16:06:18
2020-01-27 16:06:29,782 load_json.py[line:30] INFO json loaded at time 2020-01-27 16:06:29
2020-01-27 16:06:43,490 load_json.py[line:30] INFO json loaded at time 2020-01-27 16:06:43
2020-01-27 16:06:58,872 load_json.py[line:30] INFO json loaded at time 2020-01-27 16:06:58
2020-01-27 16:07:04,882 load_json.py[line:30] INFO json loaded at time 2020-01-27 16:07:04
2020-01-27 16:07:11,363 load_json.py[line:33] ERROR json load failed, waiting for around 15 seconds
2020-01-27 16:07:11,364 load_json.py[line:34] ERROR 'data'
Traceback (most recent call last):
  File "load_json.py", line 28, in load_response
    if not response['data']['listByArea']:
KeyError: 'data'
2020-01-27 16:07:32,096 load_json.py[line:30] INFO json loaded at time 2020-01-27 16:07:32
2020-01-27 16:07:44,690 load_json.py[line:30] INFO json loaded at time 2020-01-27 16:07:44
2020-01-27 16:07:55,539 load_json.py[line:30] INFO json loaded at time 2020-01-27 16:07:55
2020-01-27 16:08:07,123 load_json.py[line:30] INFO json loaded at time 2020-01-27 16:08:07
2020-01-27 16:08:15,066 load_json.py[line:30] INFO json loaded at time 2020-01-27 16:08:15
2020-01-27 16:08:23,402 load_json.py[line:30] INFO json loaded at time 2020-01-27 16:08:23
2020-01-27 16:08:38,020 load_json.py[line:30] INFO json loaded at time 2020-01-27 16:08:38
2020-01-27 16:08:48,016 load_json.py[line:30] INFO json loaded at time 2020-01-27 16:08:48
2020-01-27 16:08:57,280 load_json.py[line:33] ERROR json load failed, waiting for around 15 seconds
2020-01-27 16:08:57,281 load_json.py[line:34] ERROR 'data'
Traceback (most recent call last):
  File "load_json.py", line 28, in load_response
    if not response['data']['listByArea']:
KeyError: 'data'
2020-01-27 16:09:13,917 load_json.py[line:30] INFO json loaded at time 2020-01-27 16:09:13
2020-01-27 16:09:27,022 load_json.py[line:33] ERROR json load failed, waiting for around 15 seconds
2020-01-27 16:09:27,023 load_json.py[line:34] ERROR 'data'
Traceback (most recent call last):
  File "load_json.py", line 28, in load_response
    if not response['data']['listByArea']:
KeyError: 'data'
2020-01-27 16:09:45,648 load_json.py[line:33] ERROR json load failed, waiting for around 15 seconds
2020-01-27 16:09:45,649 load_json.py[line:34] ERROR 'data'
Traceback (most recent call last):
  File "load_json.py", line 28, in load_response
    if not response['data']['listByArea']:
KeyError: 'data'

During handling of the above exception, another exception occurred:

Traceback (most recent call last):
  File "load_json.py", line 28, in load_response
    if not response['data']['listByArea']:
KeyError: 'data'
2020-01-27 16:10:05,570 load_json.py[line:30] INFO json loaded at time 2020-01-27 16:10:05
2020-01-27 16:10:14,790 load_json.py[line:30] INFO json loaded at time 2020-01-27 16:10:14
2020-01-27 16:10:26,424 load_json.py[line:30] INFO json loaded at time 2020-01-27 16:10:26
2020-01-27 16:10:41,337 load_json.py[line:33] ERROR json load failed, waiting for around 15 seconds
2020-01-27 16:10:41,337 load_json.py[line:34] ERROR 'data'
Traceback (most recent call last):
  File "load_json.py", line 28, in load_response
    if not response['data']['listByArea']:
KeyError: 'data'
2020-01-27 16:10:58,172 load_json.py[line:33] ERROR json load failed, waiting for around 15 seconds
2020-01-27 16:10:58,172 load_json.py[line:34] ERROR 'data'
Traceback (most recent call last):
  File "load_json.py", line 28, in load_response
    if not response['data']['listByArea']:
KeyError: 'data'

During handling of the above exception, another exception occurred:

Traceback (most recent call last):
  File "load_json.py", line 28, in load_response
    if not response['data']['listByArea']:
KeyError: 'data'
2020-01-27 16:11:18,878 load_json.py[line:30] INFO json loaded at time 2020-01-27 16:11:18
2020-01-27 16:11:26,469 load_json.py[line:30] INFO json loaded at time 2020-01-27 16:11:26
2020-01-27 16:11:34,753 load_json.py[line:33] ERROR json load failed, waiting for around 15 seconds
2020-01-27 16:11:34,753 load_json.py[line:34] ERROR 'data'
Traceback (most recent call last):
  File "load_json.py", line 28, in load_response
    if not response['data']['listByArea']:
KeyError: 'data'
2020-01-27 16:11:50,906 load_json.py[line:30] INFO json loaded at time 2020-01-27 16:11:50
2020-01-27 16:12:00,360 load_json.py[line:33] ERROR json load failed, waiting for around 15 seconds
2020-01-27 16:12:00,360 load_json.py[line:34] ERROR 'data'
Traceback (most recent call last):
  File "load_json.py", line 28, in load_response
    if not response['data']['listByArea']:
KeyError: 'data'
2020-01-27 16:12:17,219 load_json.py[line:33] ERROR json load failed, waiting for around 15 seconds
2020-01-27 16:12:17,219 load_json.py[line:34] ERROR 'data'
Traceback (most recent call last):
  File "load_json.py", line 28, in load_response
    if not response['data']['listByArea']:
KeyError: 'data'

During handling of the above exception, another exception occurred:

Traceback (most recent call last):
  File "load_json.py", line 28, in load_response
    if not response['data']['listByArea']:
KeyError: 'data'
2020-01-27 16:12:35,365 load_json.py[line:30] INFO json loaded at time 2020-01-27 16:12:35
2020-01-27 16:12:45,432 load_json.py[line:33] ERROR json load failed, waiting for around 15 seconds
2020-01-27 16:12:45,433 load_json.py[line:34] ERROR 'data'
Traceback (most recent call last):
  File "load_json.py", line 28, in load_response
    if not response['data']['listByArea']:
KeyError: 'data'
2020-01-27 16:13:02,503 load_json.py[line:30] INFO json loaded at time 2020-01-27 16:13:02
2020-01-27 16:13:16,224 load_json.py[line:30] INFO json loaded at time 2020-01-27 16:13:16
2020-01-27 16:13:30,189 load_json.py[line:30] INFO json loaded at time 2020-01-27 16:13:30
2020-01-27 16:13:37,690 load_json.py[line:30] INFO json loaded at time 2020-01-27 16:13:37
2020-01-27 16:13:47,011 load_json.py[line:30] INFO json loaded at time 2020-01-27 16:13:47
2020-01-27 16:13:57,699 load_json.py[line:30] INFO json loaded at time 2020-01-27 16:13:57
2020-01-27 16:14:04,265 load_json.py[line:33] ERROR json load failed, waiting for around 15 seconds
2020-01-27 16:14:04,266 load_json.py[line:34] ERROR 'data'
Traceback (most recent call last):
  File "load_json.py", line 28, in load_response
    if not response['data']['listByArea']:
KeyError: 'data'
2020-01-27 16:14:21,691 load_json.py[line:30] INFO json loaded at time 2020-01-27 16:14:21
2020-01-27 16:14:32,021 load_json.py[line:30] INFO json loaded at time 2020-01-27 16:14:32
2020-01-27 16:14:42,621 load_json.py[line:30] INFO json loaded at time 2020-01-27 16:14:42
2020-01-27 16:14:56,258 load_json.py[line:30] INFO json loaded at time 2020-01-27 16:14:56
2020-01-27 16:15:05,969 load_json.py[line:30] INFO json loaded at time 2020-01-27 16:15:05
2020-01-27 16:15:13,555 load_json.py[line:30] INFO json loaded at time 2020-01-27 16:15:13
2020-01-27 16:15:26,844 load_json.py[line:30] INFO json loaded at time 2020-01-27 16:15:26
2020-01-27 16:15:41,280 load_json.py[line:30] INFO json loaded at time 2020-01-27 16:15:41
2020-01-27 16:15:52,945 load_json.py[line:30] INFO json loaded at time 2020-01-27 16:15:52
2020-01-27 16:15:59,948 load_json.py[line:30] INFO json loaded at time 2020-01-27 16:15:59
2020-01-27 16:16:13,715 load_json.py[line:30] INFO json loaded at time 2020-01-27 16:16:13
